Workbook
Name ChoixMesuresOuNon: Références!$C$40:$C$41
Name ChoixNon: Références!$C$41:$C$41
Name ChoixTous: Références!$C$39:$C$41

Sheet Vue d'ensemble
B2: Contrôle d'un projet cloud – aide-mémoire privatim
B3: =IF(OR($C$21="",$C$21="[à compléter]"),"[Projet à compléter]",$C$21) -> [Projet à compléter]
B4: Cet outil permet de confronter un projet cloud à chacune des exigences de l'aide-mémoire de privatim (version 3.02 du 2 octobre 2026) et de documenter l'appréciation de l'organisation. L'aide-mémoire n'a pas de force obligatoire : des divergences sont possibles si l'évaluation du cadre légal le permet. Les cellules à fond crème doivent être renseignées. Le fonctionnement est décrit dans l'onglet « Références ».
B6: A. Questions de principe — à renseigner en premier
B7: Les réponses déterminent les exigences applicables ; les exigences sans objet sont grisées et exclues des calculs. « Ne peut être exclu » et « À déterminer » sont traités comme « Oui » par précaution.
B8: Question | C8: Réponse | D8: Effet sur le contrôle
B9: Des données personnelles sensibles (y compris le profilage) sont-elles traitées dans le service ? | C9: Ne peut être exclu | D9: =IF($C$9="Non","Exigences propres aux données sensibles (ch. 2.3 b) sans objet.","Exigences renforcées pour les données sensibles activées (ch. 2.3 b)"&IF($C$9="Oui",".",".")) -> Exigences renforcées pour les données sensibles activées (ch. 2.3 b).
B10: Des données sont-elles soumises à une obligation légale de garder le secret (secret de fonction, art. 320 CP ; secrets particuliers ; secret professionnel, art. 321 CP) ? | C10: Ne peut être exclu | D10: =IF($C$10="Non","Exigence relative au secret et aux auxiliaires (2.3-06) sans objet.","Exigences relatives aux secrets légaux activées (ch. 2.3 c : auxiliaires, motif justificatif)"&IF($C$10="Oui",".",".")) -> Exigences relatives aux secrets légaux activées (ch. 2.3 c : auxiliaires, motif justificatif).
B11: Le fournisseur ou son groupe est-il soumis au CLOUD Act ou à un droit étranger comparable ? | C11: Ne peut être exclu | D11: =IF($C$11="Non","Exigences relatives aux accès des autorités étrangères sans objet ; documenter le siège et l'actionnariat du groupe.","Exigences relatives aux accès des autorités étrangères activées (2.2-04 et 2.2-05), y compris en cas d'hébergement en Suisse.") -> Exigences relatives aux accès des autorités étrangères activées (2.2-04 et 2.2-05), y compris en cas d'hébergement en Suisse.
B12: Des données sont-elles traitées à l'étranger ou accessibles depuis l'étranger, y compris pour le support à distance ? | C12: Ne peut être exclu | D12: =IF($C$12="Non — Suisse uniquement","Pas de communication à l'étranger : exigences de transfert sans objet ; garantir par contrat la localisation et l'absence d'accès depuis l'étranger.",IF($C$12="Oui — État adéquat (annexe 1 OPDo)","Communication admise vers un État adéquat ; pour les États-Unis, seulement vers une entreprise certifiée DPF.",IF($C$12="Oui — État non adéquat","Garanties contractuelles et mesures supplémentaires requises (2.2-03).","À clarifier : traité comme un État non adéquat par précaution."))) -> À clarifier : traité comme un État non adéquat par précaution.
B13: Le service est-il une solution SaaS d'un grand fournisseur international (p. ex. Microsoft, Google, AWS, SAP) ? | C13: Oui | D13: =IF($C$13="Non","Position de principe du ch. 2.3 b sur les solutions SaaS des grands fournisseurs sans objet.",IF(Références!$D$31="Oui","Position de principe du ch. 2.3 b applicable (2.3-05 : sous-traitance non admissible dans la plupart des cas selon privatim) : à apprécier de manière critique, voir la position d'id est avocats dans l'onglet « Références ».","Pas de données particulières : la position de principe du ch. 2.3 b ne s'applique pas.")) -> Position de principe du ch. 2.3 b applicable (2.3-05 : sous-traitance non admissible dans la plupart des cas selon privatim) : à apprécier de manière critique, voir la position d'id est avocats dans l'onglet « Références ».
B14: Le contrat prévoit-il un droit ou un for étrangers ? | C14: À déterminer | D14: =IF($C$14="Non","Droit suisse et for en Suisse : les conditions pour un droit ou un for étrangers (2.1-06) sont sans objet.","Conditions pour un droit ou un for étrangers activées (2.1-06)"&IF($C$14="Oui","."," par précaution.")) -> Conditions pour un droit ou un for étrangers activées (2.1-06) par précaution.
B15: Qui détient les clés de chiffrement des données sensibles au repos ? | C15: À déterminer | D15: =IF(Références!$D$29<>"Oui","Pas de données sensibles : question sans incidence.",IF($C$15="L'organisation uniquement","Chiffrement par l'organisation : les conditions du chiffrement chez le fournisseur (2.3-04) sont sans objet.",IF($C$15="Pas de chiffrement au repos","L'exigence 2.3-03 (chiffrement par l'organisation) n'est pas remplie en l'état ; les conditions du chiffrement chez le fournisseur sont sans objet.","Conditions du chiffrement chez le fournisseur activées (2.3-04)"&IF($C$15="Le fournisseur (seul ou avec l'organisation)","."," par précaution.")))) -> Conditions du chiffrement chez le fournisseur activées (2.3-04) par précaution.
B17: B. Identification du contrôle
B18: Organisation (organe public) | C18: [à compléter]
B19: Canton et loi cantonale de protection des données applicable | C19: [à compléter]
B20: Autorité cantonale de protection des données compétente | C20: [à compléter]
B21: Projet ou service cloud contrôlé | C21: [à compléter]
B22: Fournisseur et groupe (société mère) | C22: [à compléter]
B23: Modèle de service | C23: [à choisir]
B24: Données et traitements concernés | C24: [à compléter]
B25: Version de l'aide-mémoire contrôlée | C25: Version 3.02 du 2 octobre 2026
B26: Contrôle effectué par (nom, fonction) | C26: [à compléter]
B27: Date du contrôle | C27: [jj.mm.aaaa]
B28: Version du document | C28: 1.0
B30: C. Tableau de bord par chapitre
B31: Décompte des exigences applicables par chapitre de l'aide-mémoire, d'après le résultat calculé dans l'onglet « Exigences privatim ».
B32: Chapitre de l'aide-mémoire | C32: Applicables | D32: OK | E32: OK moyennant mesures | F32: Non acceptables | G32: À évaluer ou à apprécier
B33: 2.1 Conception du contrat | C33: =COUNTIFS('Exigences privatim'!$B$6:$B$49,"2.1-*",'Exigences privatim'!$H$6:$H$49,"Applicable") -> 6 | D33: =COUNTIFS('Exigences privatim'!$B$6:$B$49,"2.1-*",'Exigences privatim'!$P$6:$P$49,"OK") -> 0 | E33: =COUNTIFS('Exigences privatim'!$B$6:$B$49,"2.1-*",'Exigences privatim'!$P$6:$P$49,"OK moyennant mise en œuvre de mesures") -> 0 | F33: =COUNTIFS('Exigences privatim'!$B$6:$B$49,"2.1-*",'Exigences privatim'!$P$6:$P$49,"Non acceptable") -> 0 | G33: =COUNTIFS('Exigences privatim'!$B$6:$B$49,"2.1-*",'Exigences privatim'!$P$6:$P$49,"À évaluer")+COUNTIFS('Exigences privatim'!$B$6:$B$49,"2.1-*",'Exigences privatim'!$P$6:$P$49,"À apprécier")+COUNTIFS('Exigences privatim'!$B$6:$B$49,"2.1-*",'Exigences privatim'!$P$6:$P$49,"À corriger") -> 6
B34: 2.2 Lieux des traitements des données, y compris les accès des autorités étrangères | C34: =COUNTIFS('Exigences privatim'!$B$6:$B$49,"2.2-*",'Exigences privatim'!$H$6:$H$49,"Applicable") -> 5 | D34: =COUNTIFS('Exigences privatim'!$B$6:$B$49,"2.2-*",'Exigences privatim'!$P$6:$P$49,"OK") -> 0 | E34: =COUNTIFS('Exigences privatim'!$B$6:$B$49,"2.2-*",'Exigences privatim'!$P$6:$P$49,"OK moyennant mise en œuvre de mesures") -> 0 | F34: =COUNTIFS('Exigences privatim'!$B$6:$B$49,"2.2-*",'Exigences privatim'!$P$6:$P$49,"Non acceptable") -> 0 | G34: =COUNTIFS('Exigences privatim'!$B$6:$B$49,"2.2-*",'Exigences privatim'!$P$6:$P$49,"À évaluer")+COUNTIFS('Exigences privatim'!$B$6:$B$49,"2.2-*",'Exigences privatim'!$P$6:$P$49,"À apprécier")+COUNTIFS('Exigences privatim'!$B$6:$B$49,"2.2-*",'Exigences privatim'!$P$6:$P$49,"À corriger") -> 5
B35: 2.3 Confidentialité, protection des secrets, cryptage et gestion des clés | C35: =COUNTIFS('Exigences privatim'!$B$6:$B$49,"2.3-*",'Exigences privatim'!$H$6:$H$49,"Applicable") -> 6 | D35: =COUNTIFS('Exigences privatim'!$B$6:$B$49,"2.3-*",'Exigences privatim'!$P$6:$P$49,"OK") -> 0 | E35: =COUNTIFS('Exigences privatim'!$B$6:$B$49,"2.3-*",'Exigences privatim'!$P$6:$P$49,"OK moyennant mise en œuvre de mesures") -> 0 | F35: =COUNTIFS('Exigences privatim'!$B$6:$B$49,"2.3-*",'Exigences privatim'!$P$6:$P$49,"Non acceptable") -> 0 | G35: =COUNTIFS('Exigences privatim'!$B$6:$B$49,"2.3-*",'Exigences privatim'!$P$6:$P$49,"À évaluer")+COUNTIFS('Exigences privatim'!$B$6:$B$49,"2.3-*",'Exigences privatim'!$P$6:$P$49,"À apprécier")+COUNTIFS('Exigences privatim'!$B$6:$B$49,"2.3-*",'Exigences privatim'!$P$6:$P$49,"À corriger") -> 6
B36: 2.4 Données concernant les utilisatrices et utilisateurs des services du Cloud | C36: =COUNTIFS('Exigences privatim'!$B$6:$B$49,"2.4-*",'Exigences privatim'!$H$6:$H$49,"Applicable") -> 2 | D36: =COUNTIFS('Exigences privatim'!$B$6:$B$49,"2.4-*",'Exigences privatim'!$P$6:$P$49,"OK") -> 0 | E36: =COUNTIFS('Exigences privatim'!$B$6:$B$49,"2.4-*",'Exigences privatim'!$P$6:$P$49,"OK moyennant mise en œuvre de mesures") -> 0 | F36: =COUNTIFS('Exigences privatim'!$B$6:$B$49,"2.4-*",'Exigences privatim'!$P$6:$P$49,"Non acceptable") -> 0 | G36: =COUNTIFS('Exigences privatim'!$B$6:$B$49,"2.4-*",'Exigences privatim'!$P$6:$P$49,"À évaluer")+COUNTIFS('Exigences privatim'!$B$6:$B$49,"2.4-*",'Exigences privatim'!$P$6:$P$49,"À apprécier")+COUNTIFS('Exigences privatim'!$B$6:$B$49,"2.4-*",'Exigences privatim'!$P$6:$P$49,"À corriger") -> 2
B37: 2.5 Contrats de sous-traitance (subcontracting) | C37: =COUNTIFS('Exigences privatim'!$B$6:$B$49,"2.5-*",'Exigences privatim'!$H$6:$H$49,"Applicable") -> 3 | D37: =COUNTIFS('Exigences privatim'!$B$6:$B$49,"2.5-*",'Exigences privatim'!$P$6:$P$49,"OK") -> 0 | E37: =COUNTIFS('Exigences privatim'!$B$6:$B$49,"2.5-*",'Exigences privatim'!$P$6:$P$49,"OK moyennant mise en œuvre de mesures") -> 0 | F37: =COUNTIFS('Exigences privatim'!$B$6:$B$49,"2.5-*",'Exigences privatim'!$P$6:$P$49,"Non acceptable") -> 0 | G37: =COUNTIFS('Exigences privatim'!$B$6:$B$49,"2.5-*",'Exigences privatim'!$P$6:$P$49,"À évaluer")+COUNTIFS('Exigences privatim'!$B$6:$B$49,"2.5-*",'Exigences privatim'!$P$6:$P$49,"À apprécier")+COUNTIFS('Exigences privatim'!$B$6:$B$49,"2.5-*",'Exigences privatim'!$P$6:$P$49,"À corriger") -> 3
B38: 2.6 Devoirs d’annonce | C38: =COUNTIFS('Exigences privatim'!$B$6:$B$49,"2.6-*",'Exigences privatim'!$H$6:$H$49,"Applicable") -> 2 | D38: =COUNTIFS('Exigences privatim'!$B$6:$B$49,"2.6-*",'Exigences privatim'!$P$6:$P$49,"OK") -> 0 | E38: =COUNTIFS('Exigences privatim'!$B$6:$B$49,"2.6-*",'Exigences privatim'!$P$6:$P$49,"OK moyennant mise en œuvre de mesures") -> 0 | F38: =COUNTIFS('Exigences privatim'!$B$6:$B$49,"2.6-*",'Exigences privatim'!$P$6:$P$49,"Non acceptable") -> 0 | G38: =COUNTIFS('Exigences privatim'!$B$6:$B$49,"2.6-*",'Exigences privatim'!$P$6:$P$49,"À évaluer")+COUNTIFS('Exigences privatim'!$B$6:$B$49,"2.6-*",'Exigences privatim'!$P$6:$P$49,"À apprécier")+COUNTIFS('Exigences privatim'!$B$6:$B$49,"2.6-*",'Exigences privatim'!$P$6:$P$49,"À corriger") -> 2
B39: 2.7 Droit et possibilité de contrôle | C39: =COUNTIFS('Exigences privatim'!$B$6:$B$49,"2.7-*",'Exigences privatim'!$H$6:$H$49,"Applicable") -> 3 | D39: =COUNTIFS('Exigences privatim'!$B$6:$B$49,"2.7-*",'Exigences privatim'!$P$6:$P$49,"OK") -> 0 | E39: =COUNTIFS('Exigences privatim'!$B$6:$B$49,"2.7-*",'Exigences privatim'!$P$6:$P$49,"OK moyennant mise en œuvre de mesures") -> 0 | F39: =COUNTIFS('Exigences privatim'!$B$6:$B$49,"2.7-*",'Exigences privatim'!$P$6:$P$49,"Non acceptable") -> 0 | G39: =COUNTIFS('Exigences privatim'!$B$6:$B$49,"2.7-*",'Exigences privatim'!$P$6:$P$49,"À évaluer")+COUNTIFS('Exigences privatim'!$B$6:$B$49,"2.7-*",'Exigences privatim'!$P$6:$P$49,"À apprécier")+COUNTIFS('Exigences privatim'!$B$6:$B$49,"2.7-*",'Exigences privatim'!$P$6:$P$49,"À corriger") -> 3
B40: 2.8 Mesures de sécurité de l’information | C40: =COUNTIFS('Exigences privatim'!$B$6:$B$49,"2.8-*",'Exigences privatim'!$H$6:$H$49,"Applicable") -> 1 | D40: =COUNTIFS('Exigences privatim'!$B$6:$B$49,"2.8-*",'Exigences privatim'!$P$6:$P$49,"OK") -> 0 | E40: =COUNTIFS('Exigences privatim'!$B$6:$B$49,"2.8-*",'Exigences privatim'!$P$6:$P$49,"OK moyennant mise en œuvre de mesures") -> 0 | F40: =COUNTIFS('Exigences privatim'!$B$6:$B$49,"2.8-*",'Exigences privatim'!$P$6:$P$49,"Non acceptable") -> 0 | G40: =COUNTIFS('Exigences privatim'!$B$6:$B$49,"2.8-*",'Exigences privatim'!$P$6:$P$49,"À évaluer")+COUNTIFS('Exigences privatim'!$B$6:$B$49,"2.8-*",'Exigences privatim'!$P$6:$P$49,"À apprécier")+COUNTIFS('Exigences privatim'!$B$6:$B$49,"2.8-*",'Exigences privatim'!$P$6:$P$49,"À corriger") -> 1
B41: 2.9 Obligations en cas de résiliation du contrat | C41: =COUNTIFS('Exigences privatim'!$B$6:$B$49,"2.9-*",'Exigences privatim'!$H$6:$H$49,"Applicable") -> 1 | D41: =COUNTIFS('Exigences privatim'!$B$6:$B$49,"2.9-*",'Exigences privatim'!$P$6:$P$49,"OK") -> 0 | E41: =COUNTIFS('Exigences privatim'!$B$6:$B$49,"2.9-*",'Exigences privatim'!$P$6:$P$49,"OK moyennant mise en œuvre de mesures") -> 0 | F41: =COUNTIFS('Exigences privatim'!$B$6:$B$49,"2.9-*",'Exigences privatim'!$P$6:$P$49,"Non acceptable") -> 0 | G41: =COUNTIFS('Exigences privatim'!$B$6:$B$49,"2.9-*",'Exigences privatim'!$P$6:$P$49,"À évaluer")+COUNTIFS('Exigences privatim'!$B$6:$B$49,"2.9-*",'Exigences privatim'!$P$6:$P$49,"À apprécier")+COUNTIFS('Exigences privatim'!$B$6:$B$49,"2.9-*",'Exigences privatim'!$P$6:$P$49,"À corriger") -> 1
B42: 3 Conclusions | C42: =COUNTIFS('Exigences privatim'!$B$6:$B$49,"3-*",'Exigences privatim'!$H$6:$H$49,"Applicable") -> 5 | D42: =COUNTIFS('Exigences privatim'!$B$6:$B$49,"3-*",'Exigences privatim'!$P$6:$P$49,"OK") -> 0 | E42: =COUNTIFS('Exigences privatim'!$B$6:$B$49,"3-*",'Exigences privatim'!$P$6:$P$49,"OK moyennant mise en œuvre de mesures") -> 0 | F42: =COUNTIFS('Exigences privatim'!$B$6:$B$49,"3-*",'Exigences privatim'!$P$6:$P$49,"Non acceptable") -> 0 | G42: =COUNTIFS('Exigences privatim'!$B$6:$B$49,"3-*",'Exigences privatim'!$P$6:$P$49,"À évaluer")+COUNTIFS('Exigences privatim'!$B$6:$B$49,"3-*",'Exigences privatim'!$P$6:$P$49,"À apprécier")+COUNTIFS('Exigences privatim'!$B$6:$B$49,"3-*",'Exigences privatim'!$P$6:$P$49,"À corriger") -> 5
B43: Total | C43: =SUM(C33:C42) -> 34 | D43: =SUM(D33:D42) -> 0 | E43: =SUM(E33:E42) -> 0 | F43: =SUM(F33:F42) -> 0 | G43: =SUM(G33:G42) -> 34
B45: D. Synthèse de l'évaluation
...

Sheet Exigences privatim
B2: Exigences de l'aide-mémoire privatim
B3: « Aide-mémoire sur les risques et les mesures spécifiques à la technologie du Cloud », version 3.02 du 2 octobre 2026. Chaque exigence est reformulée et rattachée à sa source. Les colonnes E (texte exact), G, H et J sont masquées pour faciliter la lecture (voir l'onglet Références). Seules les colonnes Statut, Constat, Choix et Mesures (fond crème) se saisissent. | D3: Colonne Appréciation : gris = exigence légale ; turquoise = bonne pratique ; orange = au-delà du droit ; rose = contestée. Chaque organisation doit vérifier et adapter pour elle-même cette évaluation. Si une exigence est qualifiée d'« exigence légale », un écart est automatiquement jugé non acceptable lorsqu'elle n'est pas remplie, et ne peut être accepté que moyennant mesures lorsqu'elle est partiellement remplie.
B5: N° | C5: Exigence de privatim (reformulée) | D5: Source | E5: Texte de l'aide-mémoire (copie exacte) | F5: Caractère selon le libellé | G5: Déclencheur | H5: Applicabilité | I5: Appréciation | J5: Commentaires | K5: Statut | L5: Constat / preuve / justification de l'écart | M5: Choix de l'organisation en cas d'écart | N5: Appréciation de l'écart | O5: Mesures prévues (responsable, échéance) | P5: Résultat
B6: 2.1 Conception du contrat (p. 2-3)
B7: 2.1-01 | C7: Un contrat écrit est conclu avec le fournisseur ; alternativement, l'organisation conclut un contrat-cadre ou accepte des conditions générales respectant les exigences de l'aide-mémoire. | D7: Ch. 2.1, p. 2 | E7: [Ch. 2.1, p. 2] L’organe public doit conclure un contrat écrit avec le fournisseur de services du Cloud. Alternativement, il conclut un contrat-cadre ou accepte des conditions générales (CG) qui respectent les exigences indiquées dans le présent aide-mémoire […]. | F7: Impératif | G7: Toujours | H7: =IF(IFERROR(INDEX(Références!$D$28:$D$36,MATCH($G7,Références!$B$28:$B$36,0)),"Non")="Oui","Applicable","Sans objet") -> Applicable | I7: Exigence légale | J7: La sous-traitance suppose un contrat (ou une base légale) ; la forme et le contenu minimal dépendent du droit cantonal. | K7: (à évaluer) | N7: =IF($H7<>"Applicable","",IF(OR($K7="",$K7="(à évaluer)"),"",IF(OR($K7="Remplie",$K7="Sans objet"),"Acceptable",IF(AND($I7="Exigence légale",$K7="Non remplie"),"Non acceptable",IF($M7="","(à apprécier)",IF(AND($I7="Exigence légale",$M7="Acceptable"),"Choix non admis",$M7)))))) | P7: =IF($H7<>"Applicable","",IF(OR($K7="",$K7="(à évaluer)"),"À évaluer",IF($N7="Acceptable","OK",IF($N7="Acceptable moyennant mesures","OK moyennant mise en œuvre de mesures",IF($N7="Non acceptable","Non acceptable",IF($N7="Choix non admis","À corriger","À apprécier")))))) -> À évaluer
B8: 2.1-02 | C8: Les conditions générales acceptées ne peuvent pas être modifiées unilatéralement par le fournisseur. | D8: Ch. 2.1, p. 2 | E8: [Ch. 2.1, p. 2] […] Alternativement, il conclut un contrat-cadre ou accepte des conditions générales (CG) qui respectent les exigences indiquées dans le présent aide-mémoire et qui ne peuvent pas être modifiées de manière unilatérale. | F8: Impératif | G8: Toujours | H8: =IF(IFERROR(INDEX(Références!$D$28:$D$36,MATCH($G8,Références!$B$28:$B$36,0)),"Non")="Oui","Applicable","Sans objet") -> Applicable | I8: Au-delà du droit | J8: Les conditions des grands fournisseurs évoluent par nature. Il n'est pas raisonnable d'exiger que le contrat soit figé. Les organisations doivent toutefois prendre en compte cet élément dans leur analyse du risque. Des mesures permettent de mitiger ce risque (p. ex. préavis, interdiction de réduire le niveau de protection, droit de résiliation, capacité du client d'augmenter le chiffrement, réversibilité). | K8: (à évaluer) | N8: =IF($H8<>"Applicable","",IF(OR($K8="",$K8="(à évaluer)"),"",IF(OR($K8="Remplie",$K8="Sans objet"),"Acceptable",IF(AND($I8="Exigence légale",$K8="Non remplie"),"Non acceptable",IF($M8="","(à apprécier)",IF(AND($I8="Exigence légale",$M8="Acceptable"),"Choix non admis",$M8)))))) | P8: =IF($H8<>"Applicable","",IF(OR($K8="",$K8="(à évaluer)"),"À évaluer",IF($N8="Acceptable","OK",IF($N8="Acceptable moyennant mesures","OK moyennant mise en œuvre de mesures",IF($N8="Non acceptable","Non acceptable",IF($N8="Choix non admis","À corriger","À apprécier")))))) -> À évaluer
B9: 2.1-03 | C9: Le fournisseur traite les données comme l'organisation serait autorisée à le faire elle-même : ses obligations contractuelles reprennent les conditions légales applicables à l'organisation, y compris pour les données des utilisateurs. | D9: Ch. 1, p. 1 ; ch. 2.1, p. 3, n. 3 | E9: [Ch. 1, p. 1] [L’organe public] doit s’assurer que les tiers traitent les données (personnelles) comme l’organe public le ferait lui-même […] [Ch. 2.1, p. 3] L’organe public doit élaborer les obligations contractuelles de comportement et de diligence du fournisseur de sorte qu’elles remplissent toutes les conditions que lui-même doit respecter selon la législation sur la protection des données qui s’applique à lui. En particulier, le fournisseur ne peut traiter que les données et seulement de la manière dont l’organe le ferait lui-même. [Note 3, p. 3] Principe de proportionnalité (minimisation des données, durée de conservation, etc.) et finalité (le fournisseur ne peut pas traiter des données personnelles à d’autres fins que celles qui sont autorisées à l’organe public lui-même) ; ces deux aspects s’appliquent aussi aux données concernant les utilisatrices et utilisateurs des services du Cloud selon le chiffre 2.4. | F9: Impératif | G9: Toujours | H9: =IF(IFERROR(INDEX(Références!$D$28:$D$36,MATCH($G9,Références!$B$28:$B$36,0)),"Non")="Oui","Applicable","Sans objet") -> Applicable | I9: Exigence légale | J9: Correspond au régime de la sous-traitance du droit cantonal. Vérifier le DPA, notamment pour les finalités propres du fournisseur (voir 2.4-02). | K9: (à évaluer) | N9: =IF($H9<>"Applicable","",IF(OR($K9="",$K9="(à évaluer)"),"",IF(OR($K9="Remplie",$K9="Sans objet"),"Acceptable",IF(AND($I9="Exigence légale",$K9="Non remplie"),"Non acceptable",IF($M9="","(à apprécier)",IF(AND($I9="Exigence légale",$M9="Acceptable"),"Choix non admis",$M9)))))) | P9: =IF($H9<>"Applicable","",IF(OR($K9="",$K9="(à évaluer)"),"À évaluer",IF($N9="Acceptable","OK",IF($N9="Acceptable moyennant mesures","OK moyennant mise en œuvre de mesures",IF($N9="Non acceptable","Non acceptable",IF($N9="Choix non admis","À corriger","À apprécier")))))) -> À évaluer
B10: 2.1-04 | C10: Le fournisseur participe à l'exécution des droits des personnes concernées (rectification, effacement). | D10: Ch. 2.1, p. 3 | E10: [Ch. 2.1, p. 3] De plus, le fournisseur doit participer à l’exécution des droits des personnes concernées découlant de la législation sur la protection des données (prétentions de l’effacement des données et de la correction des données). | F10: Impératif | G10: Toujours | H10: =IF(IFERROR(INDEX(Références!$D$28:$D$36,MATCH($G10,Références!$B$28:$B$36,0)),"Non")="Oui","Applicable","Sans objet") -> Applicable | I10: Exigence légale | J10: Usuel dans les DPA (assistance au responsable du traitement). | K10: (à évaluer) | N10: =IF($H10<>"Applicable","",IF(OR($K10="",$K10="(à évaluer)"),"",IF(OR($K10="Remplie",$K10="Sans objet"),"Acceptable",IF(AND($I10="Exigence légale",$K10="Non remplie"),"Non acceptable",IF($M10="","(à apprécier)",IF(AND($I10="Exigence légale",$M10="Acceptable"),"Choix non admis",$M10)))))) | P10: =IF($H10<>"Applicable","",IF(OR($K10="",$K10="(à évaluer)"),"À évaluer",IF($N10="Acceptable","OK",IF($N10="Acceptable moyennant mesures","OK moyennant mise en œuvre de mesures",IF($N10="Non acceptable","Non acceptable",IF($N10="Choix non admis","À corriger","À apprécier")))))) -> À évaluer
B11: 2.1-05 | C11: Le contrat est en principe soumis au droit suisse, avec un for en Suisse, de sorte que les obligations du fournisseur puissent être défendues devant des tribunaux facilement accessibles, selon un régime juridique connu de l'organisation. | D11: Ch. 2.1, p. 3 | E11: [Ch. 2.1, p. 3] La défense des obligations contractuelles devant des tribunaux faciles d’accès pour l’organe public doit être possible selon un régime juridique connu de lui. En principe, une relation contractuelle doit être soumise au droit suisse et il faut convenir d’un for en Suisse pour les décisions portant sur des conflits découlant du contrat. | F11: Principe | G11: Toujours | H11: =IF(IFERROR(INDEX(Références!$D$28:$D$36,MATCH($G11,Références!$B$28:$B$36,0)),"Non")="Oui","Applicable","Sans objet") -> Applicable | I11: Bonne pratique | J11: Le droit n'impose ni droit ni for déterminés. Il s'agit toutefois d'une exigence souhaitable lorsque cela est possible. | K11: (à évaluer) | N11: =IF($H11<>"Applicable","",IF(OR($K11="",$K11="(à évaluer)"),"",IF(OR($K11="Remplie",$K11="Sans objet"),"Acceptable",IF(AND($I11="Exigence légale",$K11="Non remplie"),"Non acceptable",IF($M11="","(à apprécier)",IF(AND($I11="Exigence légale",$M11="Acceptable"),"Choix non admis",$M11)))))) | P11: =IF($H11<>"Applicable","",IF(OR($K11="",$K11="(à évaluer)"),"À évaluer",IF($N11="Acceptable","OK",IF($N11="Acceptable moyennant mesures","OK moyennant mise en œuvre de mesures",IF($N11="Non acceptable","Non acceptable",IF($N11="Choix non admis","À corriger","À apprécier")))))) -> À évaluer
B12: 2.1-06 | C12: Un droit ou un for étrangers ne sont convenus que dans des cas justifiés et s'il n'en résulte aucun risque supplémentaire pour les droits fondamentaux, notamment si les données peuvent être efficacement protégées par chiffrement contre l'accès de tiers (y compris du fournisseur) ou, hors données particulières, si la législation sur la protection des données applicable offre un niveau de protection équivalent et que des sanctions efficaces et dissuasives menacent le fournisseur (p. ex. RGPD). | D12: Ch. 2.1, p. 3, n. 4-5 | E12: [Ch. 2.1, p. 3] Dans des cas justifiés, il est possible de convenir que le droit d’un autre Etat et un for étranger s’appliquent s’il n’y a aucun risque supplémentaire pour les droits fondamentaux des personnes concernées, notamment, lorsque : – les données peuvent être protégées de manière efficace, par le biais du cryptage, contre l’accès de tiers (et même du fournisseur du service Cloud [chiffre 2.3]) ou, – sous condition qu’il ne s’agit pas de données particulières, si la législation sur la protection des données dispose d’un niveau de protection équivalent et que des sanctions efficaces et dissuasives menacent le fournisseur en cas de violation (p. ex. RGPD de l’UE). [Note 4, p. 3] Le terme « données particulières » est utilisé dans le présent document comme terme générique pour toutes les données personnelles avec un besoin de protection élevé, c’est-à-dire les données personnelles sensibles, les profils de la personnalité et les données personnelles sous l’obligation légale de garder le secret. [Note 5, p. 3] Les parties ne peuvent pas choisir la législation sur la protection des données ; celle-ci découle du champ d’application personnel, à raison de la matière et à raison du lieu de la législation sur la protection des données elle-même. | F12: Faculté | G12: Droit étranger | H12: =IF(IFERROR(INDEX(Références!$D$28:$D$36,MATCH($G12,Références!$B$28:$B$36,0)),"Non")="Oui","Applicable","Sans objet") -> Applicable | I12: Au-delà du droit | J12: Exiger l'absence de « tout risque supplémentaire » est plus strict que le droit, qui n'impose ni droit ni for déterminés. L'appréciation porte sur l'effectivité de l'exécution du contrat. | K12: (à évaluer) | N12: =IF($H12<>"Applicable","",IF(OR($K12="",$K12="(à évaluer)"),"",IF(OR($K12="Remplie",$K12="Sans objet"),"Acceptable",IF(AND($I12="Exigence légale",$K12="Non remplie"),"Non acceptable",IF($M12="","(à apprécier)",IF(AND($I12="Exigence légale",$M12="Acceptable"),"Choix non admis",$M12)))))) | P12: =IF($H12<>"Applicable","",IF(OR($K12="",$K12="(à évaluer)"),"À évaluer",IF($N12="Acceptable","OK",IF($N12="Acceptable moyennant mesures","OK moyennant mise en œuvre de mesures",IF($N12="Non acceptable","Non acceptable",IF($N12="Choix non admis","À corriger","À apprécier")))))) -> À évaluer
B13: 2.2 Lieux des traitements des données, y compris les accès des autorités étrangères (p. 3-4)
B14: 2.2-01 | C14: Le fournisseur déclare les États dans lesquels il exploite l'infrastructure traitant les données, y compris les données des utilisateurs. | D14: Ch. 2.2, p. 3 | E14: [Ch. 2.2, p. 3] Le fournisseur de services du Cloud doit déclarer dans quels Etats il exploite son infrastructure Cloud pour le traitement des données personnelles (y c. celles selon le chiffre 2.4) afin que l’organe public puisse évaluer la licéité des transferts de données à l’étranger et, dans le cadre de l’évaluation des risques, prendre en considération les risques liés aux lieux où se trouvent les serveurs. | F14: Impératif | G14: Toujours | H14: =IF(IFERROR(INDEX(Références!$D$28:$D$36,MATCH($G14,Références!$B$28:$B$36,0)),"Non")="Oui","Applicable","Sans objet") -> Applicable | I14: Exigence légale | J14: Important pour apprécier la licéité des communications à l'étranger ; usuel dans la documentation des grands fournisseurs. | K14: (à évaluer) | N14: =IF($H14<>"Applicable","",IF(OR($K14="",$K14="(à évaluer)"),"",IF(OR($K14="Remplie",$K14="Sans objet"),"Acceptable",IF(AND($I14="Exigence légale",$K14="Non remplie"),"Non acceptable",IF($M14="","(à apprécier)",IF(AND($I14="Exigence légale",$M14="Acceptable"),"Choix non admis",$M14)))))) | P14: =IF($H14<>"Applicable","",IF(OR($K14="",$K14="(à évaluer)"),"À évaluer",IF($N14="Acceptable","OK",IF($N14="Acceptable moyennant mesures","OK moyennant mise en œuvre de mesures",IF($N14="Non acceptable","Non acceptable",IF($N14="Choix non admis","À corriger","À apprécier")))))) -> À évaluer
B15: 2.2-02 | C15: Les traitements en Suisse sont préférés. | D15: Ch. 2.2, p. 4 | E15: [Ch. 2.2, p. 4] Les traitements de données qui s’effectuent en Suisse doivent être préférés (sécurité de l’infrastructure, p. ex. en relation avec les objectifs de protection comme la disponibilité, l’intégrité des données, l’imputabilité ou la traçabilité, ainsi que l’accessibilité aux contrôles, voir le chiffre 2.7). | F15: Principe | G15: Toujours | H15: =IF(IFERROR(INDEX(Références!$D$28:$D$36,MATCH($G15,Références!$B$28:$B$36,0)),"Non")="Oui","Applicable","Sans objet") -> Applicable | I15: Au-delà du droit | J15: Pas d'obligation générale de localisation en Suisse. L'hébergement en Suisse ne supprime pas le risque lié au CLOUD Act ou au paquet e-Evidence de l'UE (2.2-04). | K15: (à évaluer) | N15: =IF($H15<>"Applicable","",IF(OR($K15="",$K15="(à évaluer)"),"",IF(OR($K15="Remplie",$K15="Sans objet"),"Acceptable",IF(AND($I15="Exigence légale",$K15="Non remplie"),"Non acceptable",IF($M15="","(à apprécier)",IF(AND($I15="Exigence légale",$M15="Acceptable"),"Choix non admis",$M15)))))) | P15: =IF($H15<>"Applicable","",IF(OR($K15="",$K15="(à évaluer)"),"À évaluer",IF($N15="Acceptable","OK",IF($N15="Acceptable moyennant mesures","OK moyennant mise en œuvre de mesures",IF($N15="Non acceptable","Non acceptable",IF($N15="Choix non admis","À corriger","À apprécier")))))) -> À évaluer
B16: 2.2-03 | C16: Tout traitement à l'étranger, y compris l'accès depuis l'étranger et le recours à des sous-traitants ultérieurs, n'a lieu que vers un État assurant une protection équivalente ou moyennant des garanties contractuelles reconnues ; si l'État permet des accès d'autorités contraires aux garanties des droits fondamentaux, des mesures supplémentaires (en particulier un chiffrement efficace) rendent le transfert licite, faute de quoi il est illicite. | D16: Ch. 2.2, p. 4, n. 6-7 ; ch. 2.5, p. 7 | E16: [Ch. 2.2, p. 4] Les traitements de données dans des lieux étrangers ne sont licites que dans les Etats qui ont un niveau de protection des données équivalent ou dans lesquels une protection des données adéquate peut être atteinte contractuellement, notamment par des clauses contractuelles standard reconnues. Ce n’est pas le cas lorsque, dans l’Etat en question, des accès par les autorités sont possibles qui ne satisfont pas aux garanties constitutionnelles des droits fondamentaux (principe de légalité, principe de proportionnalité, droits des personnes concernées, accès à des tribunaux indépendants). Dans ce cas, il faut prendre des mesures supplémentaires (en particulier un cryptage efficace) afin que le transfert de données personnelles à l’étranger soit licite. [Note 6, p. 4] Sous traitement des données à l’étranger, il faut aussi comprendre l’accès d’un lieu à l’étranger à des données sauvegardées en Suisse (p. ex. pour des services d’assistance), puisque, dans ce contexte, les données sont transmises à l’étranger, du moins temporairement. [Note 7, p. 4] Voir l’annexe 1 de l’Ordonnance sur la protection des données (OPDo) sur laquelle on s’appuie directement et partiellement dans la législation cantonale et dont on peut, d’ailleurs, se servir comme référence. [Ch. 2.5, p. 7] […] si une protection des données insuffisante pour cause d’accès éventuel des autorités ne peut pas être compensée contractuellement, il est illicite d’y recourir. | F16: Impératif | G16: Étranger | H16: =IF(IFERROR(INDEX(Références!$D$28:$D$36,MATCH($G16,Références!$B$28:$B$36,0)),"Non")="Oui","Applicable","Sans objet") -> Applicable | I16: Exigence légale | J16: Correspond aux règles cantonales sur la communication à l'étranger, sous-traitants ultérieurs compris. Les États-Unis figurent à l'annexe 1 OPDo pour les entreprises certifiées DPF depuis le 15.09.2024, point que l'aide-mémoire n'aborde pas. | K16: (à évaluer) | N16: =IF($H16<>"Applicable","",IF(OR($K16="",$K16="(à évaluer)"),"",IF(OR($K16="Remplie",$K16="Sans objet"),"Acceptable",IF(AND($I16="Exigence légale",$K16="Non remplie"),"Non acceptable",IF($M16="","(à apprécier)",IF(AND($I16="Exigence légale",$M16="Acceptable"),"Choix non admis",$M16)))))) | P16: =IF($H16<>"Applicable","",IF(OR($K16="",$K16="(à évaluer)"),"À évaluer",IF($N16="Acceptable","OK",IF($N16="Acceptable moyennant mesures","OK moyennant mise en œuvre de mesures",IF($N16="Non acceptable","Non acceptable",IF($N16="Choix non admis","À corriger","À apprécier")))))) -> À évaluer
B17: 2.2-04 | C17: L'analyse tient compte du risque qu'une autorité étrangère accède aux données en vertu du CLOUD Act ou d'un droit similaire, y compris lorsque les données sont stockées en Suisse ou dans l'UE. | D17: Ch. 2.2, p. 4, n. 8-10 | E17: [Ch. 2.2, p. 4] Attention : les fournisseurs de services soumis au CLOUD Act doivent accorder aux autorités nord-américaines un droit d’accès aux données enregistrées. Celui-ci doit être accordé même si la sauvegarde n’intervient pas aux Etats-Unis, mais, par exemple, dans un Etat de l’Union européenne ou en Suisse. L’accès d’une autorité en vertu du CLOUD Act ou un décret juridique similaire d’un autre Etat serait considéré comme une communication illicite à des tiers, parce qu’elle aurait lieu sans base légale reconnue par la Suisse. Il faut tenir compte, dans l’analyse, du risque d’une telle violation du droit […]. [Note 8, p. 4] Pour savoir qui est soumis au CLOUD Act, voir le livre blanc du département de la Justice des Etats-Unis d’avril 2019, en particulier la page 8 : <https://www.justice.gov/opa/press-release/file/1153446/download>. [Note 9, p. 4] Clarifying Lawful Overseas Use of Data Act (CLOUD Act), H.R. 4943, <https://www.congress.gov/bill/115th-congress/house-bill/4943>. [Note 10, p. 4] Dans la mesure où des autorités peuvent accéder sans en informer l’organe public responsable, on ne peut pas évaluer la probabilité d’occurrence (parce qu’elle est invérifiable) de sorte que l’attention porte sur l’étendue des dommages où la qualité des données est déterminante (données personnelles particulières). | F17: Impératif | G17: CLOUD Act | H17: =IF(IFERROR(INDEX(Références!$D$28:$D$36,MATCH($G17,Références!$B$28:$B$36,0)),"Non")="Oui","Applicable","Sans objet") -> Applicable | I17: Exigence légale | J17: Le risque d'accès hors des voies de l'entraide internationale doit être pris en compte dans l'analyse au regard des art. 320 et 321 CP ; pour savoir si le fournisseur est soumis au CLOUD Act, privatim renvoie au livre blanc du Département de la justice des États-Unis (note 8). Du point de vue de la protection des données, il ne peut pas être exigé davantage que le contrôle effectué par le Conseil fédéral. La méthode de la note 10, qui tient la probabilité pour invérifiable, est contestable : elle contredit l'approche par les risques des ch. 2 et 3, et la probabilité peut être appréciée sur des éléments vérifiables. L'aide-mémoire ne tient pas compte du paquet e-Evidence de l'UE. | K17: (à évaluer) | N17: =IF($H17<>"Applicable","",IF(OR($K17="",$K17="(à évaluer)"),"",IF(OR($K17="Remplie",$K17="Sans objet"),"Acceptable",IF(AND($I17="Exigence légale",$K17="Non remplie"),"Non acceptable",IF($M17="","(à apprécier)",IF(AND($I17="Exigence légale",$M17="Acceptable"),"Choix non admis",$M17)))))) | P17: =IF($H17<>"Applicable","",IF(OR($K17="",$K17="(à évaluer)"),"À évaluer",IF($N17="Acceptable","OK",IF($N17="Acceptable moyennant mesures","OK moyennant mise en œuvre de mesures",IF($N17="Non acceptable","Non acceptable",IF($N17="Choix non admis","À corriger","À apprécier")))))) -> À évaluer
B18: 2.2-05 | C18: Le fournisseur s'engage contractuellement à exercer toutes les voies de recours contre la divulgation des données et à informer immédiatement l'organisation des demandes de communication d'autorités, dans la mesure où il y est autorisé. | D18: Ch. 2.2, p. 4 | E18: [Ch. 2.2, p. 4] […] et réduire ce risque autant que possible par des mesures contractuelles (surtout l’obligation du fournisseur de Cloud de saisir toutes les voies de recours pour empêcher la divulgation des données et informer immédiatement l’organe public des demandes de communication par des autorités dans la mesure où le fournisseur de Cloud y est autorisé). | F18: Impératif | G18: CLOUD Act | H18: =IF(IFERROR(INDEX(Références!$D$28:$D$36,MATCH($G18,Références!$B$28:$B$36,0)),"Non")="Oui","Applicable","Sans objet") -> Applicable | I18: Bonne pratique | J18: Engagements usuels chez les grands fournisseurs (clause 15 des clauses contractuelles types) ; vérifier leur portée et les limites liées aux interdictions de notifier. | K18: (à évaluer) | N18: =IF($H18<>"Applicable","",IF(OR($K18="",$K18="(à évaluer)"),"",IF(OR($K18="Remplie",$K18="Sans objet"),"Acceptable",IF(AND($I18="Exigence légale",$K18="Non remplie"),"Non acceptable",IF($M18="","(à apprécier)",IF(AND($I18="Exigence légale",$M18="Acceptable"),"Choix non admis",$M18)))))) | P18: =IF($H18<>"Applicable","",IF(OR($K18="",$K18="(à évaluer)"),"À évaluer",IF($N18="Acceptable","OK",IF($N18="Acceptable moyennant mesures","OK moyennant mise en œuvre de mesures",IF($N18="Non acceptable","Non acceptable",IF($N18="Choix non admis","À corriger","À apprécier")))))) -> À évaluer
B19: 2.3 Confidentialité, protection des secrets, cryptage et gestion des clés (p. 5-6)
B20: 2.3-01 | C20: Toutes les données, y compris celles des utilisateurs, sont protégées contre les accès non autorisés de tiers : chiffrement au moins pendant la transmission, selon l'état de la technique, et mesures de confidentialité pendant le traitement par le fournisseur ; si le fournisseur conserve les clés de données sensibles, il les protège et garantit l'intégrité du chiffrement. | D20: Ch. 2.3 a et b, p. 5, n. 12 | E20: [Ch. 2.3 a, p. 5] Les données personnelles traitées par le fournisseur du Cloud (y c. celles selon le chiffre 2.4) doivent être protégées contre les accès non autorisés de tiers. Indépendamment du fait qu’il s’agisse de données personnelles « simples » ou particulières, elles doivent être cryptées, du moins lors de leur transmission (« data in transit »), selon l’état actuel de la technologie. La confidentialité doit être préservée par des mesures appropriées lorsque le fournisseur du Cloud traite les données. Tant que cela est réalisé par le cryptage, il convient de noter que les données sauvegardées par cryptage (« data at rest ») ne restent pas cryptées sur une base régulière durant la suite de leur traitement (« data in process »). [Note 12, p. 5] Cela s’applique notamment lors de l’utilisation des offres de la plate-forme en tant que service (PaaS) et du logiciel en tant que service (SaaS). [Ch. 2.3 b, p. 5] […] De plus, le fournisseur du service du Cloud doit protéger les clés de la perte et de la soustraction, ainsi que de l’utilisation et de la prise de connaissance abusives. Il doit aussi garantir que les données ne soient pas compromises lors du processus de cryptage. | F20: Impératif | G20: Toujours | H20: =IF(IFERROR(INDEX(Références!$D$28:$D$36,MATCH($G20,Références!$B$28:$B$36,0)),"Non")="Oui","Applicable","Sans objet") -> Applicable | I20: Bonne pratique | J20: Rappel du devoir de sécurité ; mesures en principe satisfaites par les services cloud usuels. Les données ne restent en règle générale pas chiffrées pendant leur traitement en mode PaaS ou SaaS. | K20: (à évaluer) | N20: =IF($H20<>"Applicable","",IF(OR($K20="",$K20="(à évaluer)"),"",IF(OR($K20="Remplie",$K20="Sans objet"),"Acceptable",IF(AND($I20="Exigence légale",$K20="Non remplie"),"Non acceptable",IF($M20="","(à apprécier)",IF(AND($I20="Exigence légale",$M20="Acceptable"),"Choix non admis",$M20)))))) | P20: =IF($H20<>"Applicable","",IF(OR($K20="",$K20="(à évaluer)"),"À évaluer",IF($N20="Acceptable","OK",IF($N20="Acceptable moyennant mesures","OK moyennant mise en œuvre de mesures",IF($N20="Non acceptable","Non acceptable",IF($N20="Choix non admis","À corriger","À apprécier")))))) -> À évaluer
B21: 2.3-02 | C21: Pour les données sensibles, des exigences de confidentialité plus élevées sont posées et intégrées à la gestion des risques. | D21: Ch. 2.3 b, p. 5 | E21: [Ch. 2.3 b, p. 5] En cas de données personnelles sensibles, il faut tenir compte, en plus, du fait que plusieurs risques ou tous les risques mentionnés ici en lien avec la confidentialité pour les services du Cloud existent. Il faut alors poser des exigences plus élevées pour préserver la confidentialité des données et les prendre en compte dans la gestion des risques […] | F21: Impératif | G21: Données sensibles | H21: =IF(IFERROR(INDEX(Références!$D$28:$D$36,MATCH($G21,Références!$B$28:$B$36,0)),"Non")="Oui","Applicable","Sans objet") -> Applicable | I21: Bonne pratique | J21: Conforme à la proportionnalité des mesures de sécurité ; le niveau requis dépend de l'intérêt concret des données, et pas seulement de leur qualification (voir G3). Au demeurant, si des mesures jugées appropriées pour des données « normales » peuvent aussi être suffisantes pour des données sensibles, il n'est pas automatiquement nécessaire de prévoir des mesures supplémentaires. | K21: (à évaluer) | N21: =IF($H21<>"Applicable","",IF(OR($K21="",$K21="(à évaluer)"),"",IF(OR($K21="Remplie",$K21="Sans objet"),"Acceptable",IF(AND($I21="Exigence légale",$K21="Non remplie"),"Non acceptable",IF($M21="","(à apprécier)",IF(AND($I21="Exigence légale",$M21="Acceptable"),"Choix non admis",$M21)))))) | P21: =IF($H21<>"Applicable","",IF(OR($K21="",$K21="(à évaluer)"),"À évaluer",IF($N21="Acceptable","OK",IF($N21="Acceptable moyennant mesures","OK moyennant mise en œuvre de mesures",IF($N21="Non acceptable","Non acceptable",IF($N21="Choix non admis","À corriger","À apprécier")))))) -> À évaluer
B22: 2.3-03 | C22: Les données sensibles sont chiffrées par l'organisation elle-même, avec des clés disponibles uniquement pour elle et protégées contre la perte, la soustraction et l'usage abusif. | D22: Ch. 2.3 b, p. 5, n. 13 | E22: [Ch. 2.3 b, p. 5] Les données doivent être cryptées et le cryptage doit être réalisé par l’organe public. Les clés ne doivent être disponibles que pour l’organe public. Elles doivent être protégées de la perte et de la soustraction, ainsi que de l’utilisation et de la prise de connaissance abusives. [Note 13, p. 5] De même, les considérations technologiques pour assurer le traitement sécurisé d’informations sensibles par plusieurs parties de l’Office fédéral de la cybersécurité OFCS du 28 mai 2026 (ch.2.2 T-1) que l’on peut consulter sous : <https://www.bacs.admin.ch/fr/26-tech-sens-info-fr>. | F22: Principe | G22: Données sensibles | H22: =IF(IFERROR(INDEX(Références!$D$28:$D$36,MATCH($G22,Références!$B$28:$B$36,0)),"Non")="Oui","Applicable","Sans objet") -> Applicable | I22: Au-delà du droit | J22: Aucune base légale n'impose un chiffrement côté client pour toutes les données sensibles ; le droit exige des mesures adaptées au risque. La règle rend inutilisables de nombreuses fonctions SaaS et doit être appréciée au regard des bénéfices et des autres mesures (voir G3 et G5). | K22: (à évaluer) | N22: =IF($H22<>"Applicable","",IF(OR($K22="",$K22="(à évaluer)"),"",IF(OR($K22="Remplie",$K22="Sans objet"),"Acceptable",IF(AND($I22="Exigence légale",$K22="Non remplie"),"Non acceptable",IF($M22="","(à apprécier)",IF(AND($I22="Exigence légale",$M22="Acceptable"),"Choix non admis",$M22)))))) | P22: =IF($H22<>"Applicable","",IF(OR($K22="",$K22="(à évaluer)"),"À évaluer",IF($N22="Acceptable","OK",IF($N22="Acceptable moyennant mesures","OK moyennant mise en œuvre de mesures",IF($N22="Non acceptable","Non acceptable",IF($N22="Choix non admis","À corriger","À apprécier")))))) -> À évaluer
B23: 2.3-04 | C23: Si le chiffrement des données sensibles est géré par le fournisseur, l'organisation établit que ce choix n'entraîne pas de risque inacceptable pour les droits fondamentaux ; le fournisseur s'engage à n'utiliser les clés qu'avec son consentement exprès, et les accès sont consignés dans un procès-verbal. | D23: Ch. 2.3 b, p. 5 | E23: [Ch. 2.3 b, p. 5] Un cryptage peut être envisagé chez le fournisseur de services du Cloud seulement si cela ne fait pas encourir des risques inacceptables aux droits fondamentaux des personnes concernées (ce que l’organe public doit indiquer de manière pertinente). Dans ce cas, il faut tenir compte du niveau auquel le cryptage a lieu (application, banque de données ou disque dur). Le fournisseur de services du Cloud peut conserver les clés s’il s’engage par contrat à les utiliser uniquement avec le consentement exprès de l’organe public. Il faut tenir un procès-verbal des accès. […] | F23: Impératif | G23: Clés fournisseur | H23: =IF(IFERROR(INDEX(Références!$D$28:$D$36,MATCH($G23,Références!$B$28:$B$36,0)),"Non")="Oui","Applicable","Sans objet") -> Applicable | I23: Bonne pratique | J23: Exige une justification documentée, ce qui correspond à l'approche fondée sur les risques. Consentement exprès et procès-verbal : mécanismes de type « customer lockbox » ou module matériel dédié, avec leurs exceptions. | K23: (à évaluer) | N23: =IF($H23<>"Applicable","",IF(OR($K23="",$K23="(à évaluer)"),"",IF(OR($K23="Remplie",$K23="Sans objet"),"Acceptable",IF(AND($I23="Exigence légale",$K23="Non remplie"),"Non acceptable",IF($M23="","(à apprécier)",IF(AND($I23="Exigence légale",$M23="Acceptable"),"Choix non admis",$M23)))))) | P23: =IF($H23<>"Applicable","",IF(OR($K23="",$K23="(à évaluer)"),"À évaluer",IF($N23="Acceptable","OK",IF($N23="Acceptable moyennant mesures","OK moyennant mise en œuvre de mesures",IF($N23="Non acceptable","Non acceptable",IF($N23="Choix non admis","À corriger","À apprécier")))))) -> À évaluer
B24: 2.3-05 | C24: Selon privatim, la sous-traitance de données sensibles ou soumises à une obligation légale de garder le secret dans les solutions SaaS de grands fournisseurs internationaux (p. ex. Microsoft, Google, AWS, SAP) n'est pas admissible dans la plupart des cas, en raison d'un risque jugé inacceptable ; selon l'expertise qu'il cite, la sous-traitance de données sensibles dans le cloud d'un fournisseur américain constitue une atteinte grave qui ne peut se fonder sur une autorisation légale générale de sous-traiter. | D24: Ch. 2.3 b, p. 5, n. 14 ; ch. 2.2, p. 4, n. 11 | E24: [Ch. 2.3 b, p. 5] La sous-traitance de données personnelles sensibles ou soumises à une obligation légale de garder le secret dans des solutions SaaS de grands fournisseurs internationaux (comme Microsoft, Google, AWS et SAP) n’est pas admissible dans la plupart des cas en raison du risque inacceptable. [Note 14, p. 5] Voir la Résolution sur l’externalisation du traitement des données dans le Cloud du 18 novembre 2025 […]. [Ch. 2.2, p. 4] Selon une expertise de l’Université de Bâle, la sous-traitance de données personnelles sensibles dans le Cloud d’un fournisseur américain représente une grave atteinte à l’autodétermination informationnelle qui n’est pas justifiable par une autorisation légale générale pour recourir à un sous-traitant du traitement des données. [Note 11, p. 4] MARKUS SCHEFER/PHILIP GLASS, Der grundrechtskonforme Einsatz von M365 durch öffentliche Organe in der Schweiz – Eine Analyse am Beispiel des Kantons Zürich, Editions Weblaw, Bern 2023. | F24: Position de principe | G24: SaaS + particulières | H24: =IF(IFERROR(INDEX(Références!$D$28:$D$36,MATCH($G24,Références!$B$28:$B$36,0)),"Non")="Oui","Applicable","Sans objet") -> Applicable | I24: Contestée | J24: Aucune interdiction légale : la qualification formelle des données n'est pas le critère légal de la sous-traitance ni du transfert, et le risque dépend de l'intérêt concret des données. L'aide-mémoire réserve lui-même des exceptions (« dans la plupart des cas »). | K24: (à évaluer) | N24: =IF($H24<>"Applicable","",IF(OR($K24="",$K24="(à évaluer)"),"",IF(OR($K24="Remplie",$K24="Sans objet"),"Acceptable",IF(AND($I24="Exigence légale",$K24="Non remplie"),"Non acceptable",IF($M24="","(à apprécier)",IF(AND($I24="Exigence légale",$M24="Acceptable"),"Choix non admis",$M24)))))) | P24: =IF($H24<>"Applicable","",IF(OR($K24="",$K24="(à évaluer)"),"À évaluer",IF($N24="Acceptable","OK",IF($N24="Acceptable moyennant mesures","OK moyennant mise en œuvre de mesures",IF($N24="Non acceptable","Non acceptable",IF($N24="Choix non admis","À corriger","À apprécier")))))) -> À évaluer
B25: 2.3-06 | C25: Lorsque des données soumises au secret de fonction ou au secret professionnel sont accessibles au fournisseur (ou à ses sous-traitants), les conditions posées par les art. 320 et 321 CP sont respectées dans le cas concret ; en particulier, le fournisseur et, le cas échéant, ses sous-traitants sont correctement intégrés comme auxiliaires conformément aux exigences applicables (aucune obligation légale ou contractuelle ne s'oppose à la sous-traitance). | D25: Ch. 1, p. 1 ; ch. 2.3 c, p. 6 | E25: [Ch. 1, p. 1] [L’organe public] peut sous-traiter le traitement des données si des obligations légales de garder le secret (comme le secret de fonction selon l’art. 320 CP, les obligations particulières de garder le secret ou le secret professionnel) ou des actes conventionnels ne s’y opposent pas dans le contexte concret […] [Ch. 2.3 c, p. 6] Les données personnelles qui sont soumises à une obligation légale de garder le secret ne peuvent être accessibles au fournisseur du Cloud (et, le cas échéant, à son sous-traitant) seulement dans la mesure où la disposition concernant la sauvegarde du secret en question permet de recourir à des auxiliaires. Cette disposition doit aussi déterminer quelles sont les personnes auxiliaires qui entrent en ligne de compte et quelles exigences doivent être remplies pour que la protection des secrets soit assurée. La violation des dispositions concernant la sauvegarde du secret sans motif justificatif reconnu doit être considérée comme une entrave juridique de la sous-traitance et pas seulement comme un risque. | F25: Impératif | G25: Secret légal | H25: =IF(IFERROR(INDEX(Références!$D$28:$D$36,MATCH($G25,Références!$B$28:$B$36,0)),"Non")="Oui","Applicable","Sans objet") -> Applicable | I25: Exigence légale | J25: L'art. 320 ch. 1 CP vise expressément l'auxiliaire d'une autorité (teneur en vigueur depuis le 1.1.2023) et l'art. 321 ch. 1 CP les auxiliaires des professions visées. Ces dispositions ne définissent pas l'auxiliaire : les critères résultent de la jurisprudence et de la doctrine, qui admettent qu'un prestataire de services puisse l'être. Documenter ces critères (instructions, intégration, engagement de confidentialité) plutôt que rechercher une disposition spécifique. La question décisive est l'existence d'une révélation (auxiliaire, données inintelligibles pour le fournisseur) ou d'un motif justificatif (consentement, autorisation). | K25: (à évaluer) | N25: =IF($H25<>"Applicable","",IF(OR($K25="",$K25="(à évaluer)"),"",IF(OR($K25="Remplie",$K25="Sans objet"),"Acceptable",IF(AND($I25="Exigence légale",$K25="Non remplie"),"Non acceptable",IF($M25="","(à apprécier)",IF(AND($I25="Exigence légale",$M25="Acceptable"),"Choix non admis",$M25)))))) | P25: =IF($H25<>"Applicable","",IF(OR($K25="",$K25="(à évaluer)"),"À évaluer",IF($N25="Acceptable","OK",IF($N25="Acceptable moyennant mesures","OK moyennant mise en œuvre de mesures",IF($N25="Non acceptable","Non acceptable",IF($N25="Choix non admis","À corriger","À apprécier")))))) -> À évaluer
B26: 2.4 Données concernant les utilisatrices et utilisateurs des services du Cloud (p. 6)
B27: 2.4-01 | C27: Les données générées par le fournisseur ou ses services (données secondaires, télémétrie, journaux) sont traitées avec la même diligence que les données traitées par l'organisation, soumises aux mêmes dispositions contractuelles et protégées de la même manière ; le respect des droits des personnes et la suppression après un délai de conservation approprié ou requis par la loi sont réglés, en tenant compte du caractère potentiellement sensible de ces données. | D27: Ch. 2.4, p. 6 | E27: [Ch. 2.4, p. 6] En règle générale, les fournisseurs (du Cloud) ne traitent pas seulement les données personnelles transmises par l’organe public dans les services du Cloud (en particulier les données de contenu), mais aussi celles générées par eux-mêmes ou leurs services par l’intermédiaire des utilisatrices et utilisateurs (p. ex. des données secondaires, de télémétrie ou de journalisation). Ces données personnelles supplémentaires doivent être traitées avec la même diligence que celles que traite l’organe public pour accomplir ses tâches. Elles doivent être soumises aux mêmes dispositions contractuelles et il faut garantir de la même manière la licéité de leur traitement et de leur protection. Il faut régler, notamment, le respect des droits des personnes concernées et la suppression après un délai de conservation approprié ou requis par la loi et les soutenir par des mesures adéquates. […] Selon le contexte, il convient de noter que les données personnelles supplémentaires peuvent devenir des données personnelles sensibles (p. ex. lorsque des données de connexion indiquent que la personne concernée séjourne dans un hôpital psychiatrique ou dans un établissement pénitentiaire). | F27: Impératif | G27: Toujours | H27: =IF(IFERROR(INDEX(Références!$D$28:$D$36,MATCH($G27,Références!$B$28:$B$36,0)),"Non")="Oui","Applicable","Sans objet") -> Applicable | I27: Exigence légale | K27: (à évaluer) | N27: =IF($H27<>"Applicable","",IF(OR($K27="",$K27="(à évaluer)"),"",IF(OR($K27="Remplie",$K27="Sans objet"),"Acceptable",IF(AND($I27="Exigence légale",$K27="Non remplie"),"Non acceptable",IF($M27="","(à apprécier)",IF(AND($I27="Exigence légale",$M27="Acceptable"),"Choix non admis",$M27)))))) | P27: =IF($H27<>"Applicable","",IF(OR($K27="",$K27="(à évaluer)"),"À évaluer",IF($N27="Acceptable","OK",IF($N27="Acceptable moyennant mesures","OK moyennant mise en œuvre de mesures",IF($N27="Non acceptable","Non acceptable",IF($N27="Choix non admis","À corriger","À apprécier")))))) -> À évaluer
B28: 2.4-02 | C28: Ces données ne sont enregistrées et exploitées qu'à des fins également autorisées à l'organisation et lui sont communiquées de manière transparente ; un traitement à d'autres fins n'est licite que si les données sont recueillies de manière anonyme, préalablement anonymisées ou efficacement pseudonymisées. | D28: Ch. 2.4, p. 6 | E28: [Ch. 2.4, p. 6] Ces données personnelles supplémentaires doivent être enregistrées et exploitées exclusivement à des fins qui seraient aussi autorisées à l’organe public ; elles doivent être communiquées à l’organe de manière transparente. En général, il s’agit de buts qui n’ont pas un caractère personnel. Entrent en ligne de compte la planification et le rapport des capacités techniques, le maintien de la sécurité de l’information et des services, la maintenance technique de l’infrastructure ou la saisie des frais dépendant de l’utilisation, par exemple. Des traitements pour d’autres finalités sont licites uniquement si les données sont recueillies de manière anonyme, préalablement anonymisées ou efficacement pseudonymisées. | F28: Impératif | G28: Toujours | H28: =IF(IFERROR(INDEX(Références!$D$28:$D$36,MATCH($G28,Références!$B$28:$B$36,0)),"Non")="Oui","Applicable","Sans objet") -> Applicable | I28: Exigence légale | J28: Conforme au principe de finalité ; vérifier les traitements « à des fins commerciales légitimes » prévus par certains DPA. | K28: (à évaluer) | N28: =IF($H28<>"Applicable","",IF(OR($K28="",$K28="(à évaluer)"),"",IF(OR($K28="Remplie",$K28="Sans objet"),"Acceptable",IF(AND($I28="Exigence légale",$K28="Non remplie"),"Non acceptable",IF($M28="","(à apprécier)",IF(AND($I28="Exigence légale",$M28="Acceptable"),"Choix non admis",$M28)))))) | P28: =IF($H28<>"Applicable","",IF(OR($K28="",$K28="(à évaluer)"),"À évaluer",IF($N28="Acceptable","OK",IF($N28="Acceptable moyennant mesures","OK moyennant mise en œuvre de mesures",IF($N28="Non acceptable","Non acceptable",IF($N28="Choix non admis","À corriger","À apprécier")))))) -> À évaluer
B29: 2.5 Contrats de sous-traitance (subcontracting) (p. 6-7)
B30: 2.5-01 | C30: Avant la conclusion du contrat, le fournisseur annonce individuellement ses sous-traitants (y compris sa société mère et ses filiales), et le contrat indique comment il les instruit et les contrôle, chaînes de sous-traitance comprises. | D30: Ch. 2.5, p. 6 | E30: [Ch. 2.5, p. 6] L’organe public demeure aussi responsable des traitements de données que le fournisseur du Cloud transmet, pour sa part, à des tiers (y compris à la société-mère et à la société-fille). C’est pourquoi, avant la conclusion du contrat entre l’organe public et le fournisseur, ce dernier doit annoncer ses contrats de sous-traitance individuellement de façon à ce que l’organe public ait la possibilité d’évaluer la licéité des transferts de données vers l’étranger et les risques en lien avec tous les prestataires de services du Cloud impliqués. Le contrat doit indiquer les mesures par lesquelles le fournisseur du Cloud instruit et contrôle ses sous-traitants (y c. les relations avec les [chaînes de] sous-sous-traitants). | F30: Impératif | G30: Toujours | H30: =IF(IFERROR(INDEX(Références!$D$28:$D$36,MATCH($G30,Références!$B$28:$B$36,0)),"Non")="Oui","Applicable","Sans objet") -> Applicable | I30: Exigence légale | J30: Les listes publiées en ligne par les grands fournisseurs répondent en principe à l'exigence si elles sont suffisamment précises (pays, fonctions) ; les clauses de répercussion des obligations sont usuelles. | K30: (à évaluer) | N30: =IF($H30<>"Applicable","",IF(OR($K30="",$K30="(à évaluer)"),"",IF(OR($K30="Remplie",$K30="Sans objet"),"Acceptable",IF(AND($I30="Exigence légale",$K30="Non remplie"),"Non acceptable",IF($M30="","(à apprécier)",IF(AND($I30="Exigence légale",$M30="Acceptable"),"Choix non admis",$M30)))))) | P30: =IF($H30<>"Applicable","",IF(OR($K30="",$K30="(à évaluer)"),"À évaluer",IF($N30="Acceptable","OK",IF($N30="Acceptable moyennant mesures","OK moyennant mise en œuvre de mesures",IF($N30="Non acceptable","Non acceptable",IF($N30="Choix non admis","À corriger","À apprécier")))))) -> À évaluer
B31: 2.5-02 | C31: Les sous-traitants situés dans des États sans niveau de protection adéquat sont exclus. | D31: Ch. 2.5, p. 7 | E31: [Ch. 2.5, p. 7] Les sous-traitants issus de pays qui n’ont pas un niveau de protection des données adéquat devraient être exclus ; […] | F31: Recommandation | G31: Étranger | H31: =IF(IFERROR(INDEX(Références!$D$28:$D$36,MATCH($G31,Références!$B$28:$B$36,0)),"Non")="Oui","Applicable","Sans objet") -> Applicable | I31: Au-delà du droit | J31: Le droit admet des destinataires dans des États non adéquats moyennant des garanties appropriées (voir 2.2-03) ; l'exclusion n'est qu'une recommandation. | K31: (à évaluer) | N31: =IF($H31<>"Applicable","",IF(OR($K31="",$K31="(à évaluer)"),"",IF(OR($K31="Remplie",$K31="Sans objet"),"Acceptable",IF(AND($I31="Exigence légale",$K31="Non remplie"),"Non acceptable",IF($M31="","(à apprécier)",IF(AND($I31="Exigence légale",$M31="Acceptable"),"Choix non admis",$M31)))))) | P31: =IF($H31<>"Applicable","",IF(OR($K31="",$K31="(à évaluer)"),"À évaluer",IF($N31="Acceptable","OK",IF($N31="Acceptable moyennant mesures","OK moyennant mise en œuvre de mesures",IF($N31="Non acceptable","Non acceptable",IF($N31="Choix non admis","À corriger","À apprécier")))))) -> À évaluer
