Workbook
Name ChoicesMeasuresOrNot: References!$C$40:$C$41
Name ChoicesAll: References!$C$39:$C$41
Name ChoicesNotAcceptable: References!$C$41:$C$41

Sheet Overview
B2: Cloud project review – privatim fact sheet
B3: =IF(OR($C$21="",$C$21="[to be completed]"),"[Project to be completed]",$C$21) -> [Project to be completed]
B4: This tool compares a cloud project with each requirement of the privatim fact sheet (version 3.02 of 2 October 2026) and documents the organisation's assessment. The fact sheet is not binding: deviations are possible where the assessment of the legal framework allows. Cells with a cream background must be completed. The tool is explained in the “References” tab.
B6: A. Threshold questions — to be answered first
B7: The answers determine the applicable requirements; requirements that do not apply are greyed out and excluded from the calculations. “Cannot be excluded” and “To be determined” are treated as “Yes” as a precaution.
B8: Question | C8: Answer | D8: Effect on the review
B9: Are sensitive personal data (including profiling) processed in the service? | C9: Cannot be excluded | D9: =IF($C$9="No","Requirements specific to sensitive data (ch. 2.3 b) not applicable.","Enhanced requirements for sensitive data activated (ch. 2.3 b)"&IF($C$9="Yes",".",".")) -> Enhanced requirements for sensitive data activated (ch. 2.3 b).
B10: Are any data subject to a legal duty of secrecy (official secrecy, art. 320 SCC; special duties of secrecy; professional secrecy, art. 321 SCC)? | C10: Cannot be excluded | D10: =IF($C$10="No","Requirement on secrecy and auxiliaries (2.3-06) not applicable.","Requirements on legal secrecy activated (ch. 2.3 c: auxiliaries, justification)"&IF($C$10="Yes",".",".")) -> Requirements on legal secrecy activated (ch. 2.3 c: auxiliaries, justification).
B11: Is the provider or its group subject to the CLOUD Act or comparable foreign law? | C11: Cannot be excluded | D11: =IF($C$11="No","Requirements on access by foreign authorities not applicable; document the group's registered office and shareholders.","Requirements on access by foreign authorities activated (2.2-04 and 2.2-05), including where data are hosted in Switzerland.") -> Requirements on access by foreign authorities activated (2.2-04 and 2.2-05), including where data are hosted in Switzerland.
B12: Are any data processed abroad or accessible from abroad, including for remote support? | C12: Cannot be excluded | D12: =IF($C$12="No — Switzerland only","No disclosure abroad: transfer requirements not applicable; secure the data location and the absence of access from abroad by contract.",IF($C$12="Yes — adequate country (Annex 1 DPO)","Disclosure permitted to an adequate country; for the United States, only to a DPF-certified company.",IF($C$12="Yes — non-adequate country","Contractual safeguards and supplementary measures required (2.2-03).","To be clarified: treated as a non-adequate country as a precaution."))) -> To be clarified: treated as a non-adequate country as a precaution.
B13: Is the service a SaaS solution of a large international provider (e.g. Microsoft, Google, AWS, SAP)? | C13: Yes | D13: =IF($C$13="No","Policy position of ch. 2.3 b on SaaS solutions of large providers not applicable.",IF(References!$D$31="Yes","Policy position of ch. 2.3 b applicable (2.3-05: outsourcing not permissible in most cases according to privatim): to be assessed critically; see the position of id est avocats in the “References” tab.","No special data: the policy position of ch. 2.3 b does not apply.")) -> Policy position of ch. 2.3 b applicable (2.3-05: outsourcing not permissible in most cases according to privatim): to be assessed critically; see the position of id est avocats in the “References” tab.
B14: Does the contract provide for foreign law or a foreign jurisdiction? | C14: To be determined | D14: =IF($C$14="No","Swiss law and Swiss jurisdiction: the conditions for foreign law or jurisdiction (2.1-06) do not apply.","Conditions for foreign law or jurisdiction activated (2.1-06)"&IF($C$14="Yes","."," as a precaution.")) -> Conditions for foreign law or jurisdiction activated (2.1-06) as a precaution.
B15: Who holds the encryption keys for sensitive data at rest? | C15: To be determined | D15: =IF(References!$D$29<>"Yes","No sensitive data: question without effect.",IF($C$15="The organisation only","Encryption by the organisation: the conditions for encryption by the provider (2.3-04) do not apply.",IF($C$15="No encryption at rest","Requirement 2.3-03 (encryption by the organisation) is not met at this stage; the conditions for encryption by the provider do not apply.","Conditions for encryption by the provider activated (2.3-04)"&IF($C$15="The provider (alone or with the organisation)","."," as a precaution.")))) -> Conditions for encryption by the provider activated (2.3-04) as a precaution.
B17: B. Identification of the review
B18: Organisation (public body) | C18: [to be completed]
B19: Canton and applicable cantonal data protection act | C19: [to be completed]
B20: Competent cantonal data protection authority | C20: [to be completed]
B21: Cloud project or service reviewed | C21: [to be completed]
B22: Provider and group (parent company) | C22: [to be completed]
B23: Service model | C23: [to be selected]
B24: Data and processing concerned | C24: [to be completed]
B25: Version of the fact sheet reviewed | C25: Version 3.02 of 2 October 2026
B26: Review carried out by (name, position) | C26: [to be completed]
B27: Date of the review | C27: [dd.mm.yyyy]
B28: Document version | C28: 1.0
B30: C. Dashboard by chapter
B31: Count of applicable requirements by chapter of the fact sheet, based on the result calculated in the “privatim requirements” tab.
B32: Chapter of the fact sheet | C32: Applicable | D32: OK | E32: OK subject to measures | F32: Not acceptable | G32: To be assessed or decided
B33: 2.1 Contract design | C33: =COUNTIFS('privatim requirements'!$B$6:$B$49,"2.1-*",'privatim requirements'!$H$6:$H$49,"Applicable") -> 6 | D33: =COUNTIFS('privatim requirements'!$B$6:$B$49,"2.1-*",'privatim requirements'!$P$6:$P$49,"OK") -> 0 | E33: =COUNTIFS('privatim requirements'!$B$6:$B$49,"2.1-*",'privatim requirements'!$P$6:$P$49,"OK subject to implementation of measures") -> 0 | F33: =COUNTIFS('privatim requirements'!$B$6:$B$49,"2.1-*",'privatim requirements'!$P$6:$P$49,"Not acceptable") -> 0 | G33: =COUNTIFS('privatim requirements'!$B$6:$B$49,"2.1-*",'privatim requirements'!$P$6:$P$49,"To be assessed")+COUNTIFS('privatim requirements'!$B$6:$B$49,"2.1-*",'privatim requirements'!$P$6:$P$49,"To be decided")+COUNTIFS('privatim requirements'!$B$6:$B$49,"2.1-*",'privatim requirements'!$P$6:$P$49,"To be corrected") -> 6
B34: 2.2 Places of data processing, including access by foreign authorities | C34: =COUNTIFS('privatim requirements'!$B$6:$B$49,"2.2-*",'privatim requirements'!$H$6:$H$49,"Applicable") -> 5 | D34: =COUNTIFS('privatim requirements'!$B$6:$B$49,"2.2-*",'privatim requirements'!$P$6:$P$49,"OK") -> 0 | E34: =COUNTIFS('privatim requirements'!$B$6:$B$49,"2.2-*",'privatim requirements'!$P$6:$P$49,"OK subject to implementation of measures") -> 0 | F34: =COUNTIFS('privatim requirements'!$B$6:$B$49,"2.2-*",'privatim requirements'!$P$6:$P$49,"Not acceptable") -> 0 | G34: =COUNTIFS('privatim requirements'!$B$6:$B$49,"2.2-*",'privatim requirements'!$P$6:$P$49,"To be assessed")+COUNTIFS('privatim requirements'!$B$6:$B$49,"2.2-*",'privatim requirements'!$P$6:$P$49,"To be decided")+COUNTIFS('privatim requirements'!$B$6:$B$49,"2.2-*",'privatim requirements'!$P$6:$P$49,"To be corrected") -> 5
B35: 2.3 Confidentiality, protection of secrets, encryption and key management | C35: =COUNTIFS('privatim requirements'!$B$6:$B$49,"2.3-*",'privatim requirements'!$H$6:$H$49,"Applicable") -> 6 | D35: =COUNTIFS('privatim requirements'!$B$6:$B$49,"2.3-*",'privatim requirements'!$P$6:$P$49,"OK") -> 0 | E35: =COUNTIFS('privatim requirements'!$B$6:$B$49,"2.3-*",'privatim requirements'!$P$6:$P$49,"OK subject to implementation of measures") -> 0 | F35: =COUNTIFS('privatim requirements'!$B$6:$B$49,"2.3-*",'privatim requirements'!$P$6:$P$49,"Not acceptable") -> 0 | G35: =COUNTIFS('privatim requirements'!$B$6:$B$49,"2.3-*",'privatim requirements'!$P$6:$P$49,"To be assessed")+COUNTIFS('privatim requirements'!$B$6:$B$49,"2.3-*",'privatim requirements'!$P$6:$P$49,"To be decided")+COUNTIFS('privatim requirements'!$B$6:$B$49,"2.3-*",'privatim requirements'!$P$6:$P$49,"To be corrected") -> 6
B36: 2.4 Data concerning the users of the cloud services | C36: =COUNTIFS('privatim requirements'!$B$6:$B$49,"2.4-*",'privatim requirements'!$H$6:$H$49,"Applicable") -> 2 | D36: =COUNTIFS('privatim requirements'!$B$6:$B$49,"2.4-*",'privatim requirements'!$P$6:$P$49,"OK") -> 0 | E36: =COUNTIFS('privatim requirements'!$B$6:$B$49,"2.4-*",'privatim requirements'!$P$6:$P$49,"OK subject to implementation of measures") -> 0 | F36: =COUNTIFS('privatim requirements'!$B$6:$B$49,"2.4-*",'privatim requirements'!$P$6:$P$49,"Not acceptable") -> 0 | G36: =COUNTIFS('privatim requirements'!$B$6:$B$49,"2.4-*",'privatim requirements'!$P$6:$P$49,"To be assessed")+COUNTIFS('privatim requirements'!$B$6:$B$49,"2.4-*",'privatim requirements'!$P$6:$P$49,"To be decided")+COUNTIFS('privatim requirements'!$B$6:$B$49,"2.4-*",'privatim requirements'!$P$6:$P$49,"To be corrected") -> 2
B37: 2.5 Subcontracting agreements | C37: =COUNTIFS('privatim requirements'!$B$6:$B$49,"2.5-*",'privatim requirements'!$H$6:$H$49,"Applicable") -> 3 | D37: =COUNTIFS('privatim requirements'!$B$6:$B$49,"2.5-*",'privatim requirements'!$P$6:$P$49,"OK") -> 0 | E37: =COUNTIFS('privatim requirements'!$B$6:$B$49,"2.5-*",'privatim requirements'!$P$6:$P$49,"OK subject to implementation of measures") -> 0 | F37: =COUNTIFS('privatim requirements'!$B$6:$B$49,"2.5-*",'privatim requirements'!$P$6:$P$49,"Not acceptable") -> 0 | G37: =COUNTIFS('privatim requirements'!$B$6:$B$49,"2.5-*",'privatim requirements'!$P$6:$P$49,"To be assessed")+COUNTIFS('privatim requirements'!$B$6:$B$49,"2.5-*",'privatim requirements'!$P$6:$P$49,"To be decided")+COUNTIFS('privatim requirements'!$B$6:$B$49,"2.5-*",'privatim requirements'!$P$6:$P$49,"To be corrected") -> 3
B38: 2.6 Notification duties | C38: =COUNTIFS('privatim requirements'!$B$6:$B$49,"2.6-*",'privatim requirements'!$H$6:$H$49,"Applicable") -> 2 | D38: =COUNTIFS('privatim requirements'!$B$6:$B$49,"2.6-*",'privatim requirements'!$P$6:$P$49,"OK") -> 0 | E38: =COUNTIFS('privatim requirements'!$B$6:$B$49,"2.6-*",'privatim requirements'!$P$6:$P$49,"OK subject to implementation of measures") -> 0 | F38: =COUNTIFS('privatim requirements'!$B$6:$B$49,"2.6-*",'privatim requirements'!$P$6:$P$49,"Not acceptable") -> 0 | G38: =COUNTIFS('privatim requirements'!$B$6:$B$49,"2.6-*",'privatim requirements'!$P$6:$P$49,"To be assessed")+COUNTIFS('privatim requirements'!$B$6:$B$49,"2.6-*",'privatim requirements'!$P$6:$P$49,"To be decided")+COUNTIFS('privatim requirements'!$B$6:$B$49,"2.6-*",'privatim requirements'!$P$6:$P$49,"To be corrected") -> 2
B39: 2.7 Right and ability to audit | C39: =COUNTIFS('privatim requirements'!$B$6:$B$49,"2.7-*",'privatim requirements'!$H$6:$H$49,"Applicable") -> 3 | D39: =COUNTIFS('privatim requirements'!$B$6:$B$49,"2.7-*",'privatim requirements'!$P$6:$P$49,"OK") -> 0 | E39: =COUNTIFS('privatim requirements'!$B$6:$B$49,"2.7-*",'privatim requirements'!$P$6:$P$49,"OK subject to implementation of measures") -> 0 | F39: =COUNTIFS('privatim requirements'!$B$6:$B$49,"2.7-*",'privatim requirements'!$P$6:$P$49,"Not acceptable") -> 0 | G39: =COUNTIFS('privatim requirements'!$B$6:$B$49,"2.7-*",'privatim requirements'!$P$6:$P$49,"To be assessed")+COUNTIFS('privatim requirements'!$B$6:$B$49,"2.7-*",'privatim requirements'!$P$6:$P$49,"To be decided")+COUNTIFS('privatim requirements'!$B$6:$B$49,"2.7-*",'privatim requirements'!$P$6:$P$49,"To be corrected") -> 3
B40: 2.8 Information security measures | C40: =COUNTIFS('privatim requirements'!$B$6:$B$49,"2.8-*",'privatim requirements'!$H$6:$H$49,"Applicable") -> 1 | D40: =COUNTIFS('privatim requirements'!$B$6:$B$49,"2.8-*",'privatim requirements'!$P$6:$P$49,"OK") -> 0 | E40: =COUNTIFS('privatim requirements'!$B$6:$B$49,"2.8-*",'privatim requirements'!$P$6:$P$49,"OK subject to implementation of measures") -> 0 | F40: =COUNTIFS('privatim requirements'!$B$6:$B$49,"2.8-*",'privatim requirements'!$P$6:$P$49,"Not acceptable") -> 0 | G40: =COUNTIFS('privatim requirements'!$B$6:$B$49,"2.8-*",'privatim requirements'!$P$6:$P$49,"To be assessed")+COUNTIFS('privatim requirements'!$B$6:$B$49,"2.8-*",'privatim requirements'!$P$6:$P$49,"To be decided")+COUNTIFS('privatim requirements'!$B$6:$B$49,"2.8-*",'privatim requirements'!$P$6:$P$49,"To be corrected") -> 1
B41: 2.9 Obligations upon termination of the contract | C41: =COUNTIFS('privatim requirements'!$B$6:$B$49,"2.9-*",'privatim requirements'!$H$6:$H$49,"Applicable") -> 1 | D41: =COUNTIFS('privatim requirements'!$B$6:$B$49,"2.9-*",'privatim requirements'!$P$6:$P$49,"OK") -> 0 | E41: =COUNTIFS('privatim requirements'!$B$6:$B$49,"2.9-*",'privatim requirements'!$P$6:$P$49,"OK subject to implementation of measures") -> 0 | F41: =COUNTIFS('privatim requirements'!$B$6:$B$49,"2.9-*",'privatim requirements'!$P$6:$P$49,"Not acceptable") -> 0 | G41: =COUNTIFS('privatim requirements'!$B$6:$B$49,"2.9-*",'privatim requirements'!$P$6:$P$49,"To be assessed")+COUNTIFS('privatim requirements'!$B$6:$B$49,"2.9-*",'privatim requirements'!$P$6:$P$49,"To be decided")+COUNTIFS('privatim requirements'!$B$6:$B$49,"2.9-*",'privatim requirements'!$P$6:$P$49,"To be corrected") -> 1
B42: 3 Conclusions | C42: =COUNTIFS('privatim requirements'!$B$6:$B$49,"3-*",'privatim requirements'!$H$6:$H$49,"Applicable") -> 5 | D42: =COUNTIFS('privatim requirements'!$B$6:$B$49,"3-*",'privatim requirements'!$P$6:$P$49,"OK") -> 0 | E42: =COUNTIFS('privatim requirements'!$B$6:$B$49,"3-*",'privatim requirements'!$P$6:$P$49,"OK subject to implementation of measures") -> 0 | F42: =COUNTIFS('privatim requirements'!$B$6:$B$49,"3-*",'privatim requirements'!$P$6:$P$49,"Not acceptable") -> 0 | G42: =COUNTIFS('privatim requirements'!$B$6:$B$49,"3-*",'privatim requirements'!$P$6:$P$49,"To be assessed")+COUNTIFS('privatim requirements'!$B$6:$B$49,"3-*",'privatim requirements'!$P$6:$P$49,"To be decided")+COUNTIFS('privatim requirements'!$B$6:$B$49,"3-*",'privatim requirements'!$P$6:$P$49,"To be corrected") -> 5
B43: Total | C43: =SUM(C33:C42) -> 34 | D43: =SUM(D33:D42) -> 0 | E43: =SUM(E33:E42) -> 0 | F43: =SUM(F33:F42) -> 0 | G43: =SUM(G33:G42) -> 34
B45: D. Summary of the assessment
...

Sheet privatim requirements
B2: Requirements of the privatim fact sheet
B3: privatim fact sheet “Cloud-specific risks and measures”, version 3.02 of 2 October 2026. Each requirement is rephrased and linked to its source. Columns E (text of the fact sheet), G, H and J are hidden for readability (see the References tab). Only the Status, Finding, Choice and Measures columns (cream background) are to be completed. | D3: Qualification column: grey = legal requirement; turquoise = good practice; orange = beyond the law; pink = disputed. Each organisation must review and adapt this qualification for itself. Where a requirement is qualified as a “legal requirement”, a deviation is automatically deemed not acceptable if the requirement is not met, and can only be accepted subject to measures if it is partially met.
B5: No. | C5: privatim requirement (rephrased) | D5: Source | E5: Text of the fact sheet (unofficial translation) | F5: Nature according to the wording | G5: Trigger | H5: Applicability | I5: Qualification | J5: Comments | K5: Status | L5: Finding / evidence / justification of the deviation | M5: Organisation's choice in case of deviation | N5: Assessment of the deviation | O5: Planned measures (owner, deadline) | P5: Result
B6: 2.1 Contract design (p. 2-3)
B7: 2.1-01 | C7: A written contract is concluded with the provider; alternatively, the organisation concludes a framework agreement or accepts general terms and conditions that comply with the requirements of the fact sheet. | D7: Ch. 2.1, p. 2 | E7: [Ch. 2.1, p. 2] The public body must conclude a written contract with the cloud service provider. Alternatively, it concludes a framework agreement or accepts general terms and conditions (GTC) that comply with the requirements set out in this fact sheet […]. | F7: Mandatory | G7: Always | H7: =IF(IFERROR(INDEX(References!$D$28:$D$36,MATCH($G7,References!$B$28:$B$36,0)),"No")="Yes","Applicable","Not applicable") -> Applicable | I7: Legal requirement | J7: Outsourcing requires a contract (or a legal basis); the form and minimum content depend on cantonal law. | K7: (to be assessed) | N7: =IF($H7<>"Applicable","",IF(OR($K7="",$K7="(to be assessed)"),"",IF(OR($K7="Met",$K7="Not applicable"),"Acceptable",IF(AND($I7="Legal requirement",$K7="Not met"),"Not acceptable",IF($M7="","(to be decided)",IF(AND($I7="Legal requirement",$M7="Acceptable"),"Choice not permitted",$M7)))))) | P7: =IF($H7<>"Applicable","",IF(OR($K7="",$K7="(to be assessed)"),"To be assessed",IF($N7="Acceptable","OK",IF($N7="Acceptable subject to measures","OK subject to implementation of measures",IF($N7="Not acceptable","Not acceptable",IF($N7="Choice not permitted","To be corrected","To be decided")))))) -> To be assessed
B8: 2.1-02 | C8: The general terms and conditions accepted cannot be amended unilaterally by the provider. | D8: Ch. 2.1, p. 2 | E8: [Ch. 2.1, p. 2] […] Alternatively, it concludes a framework agreement or accepts general terms and conditions (GTC) that comply with the requirements set out in this fact sheet and that cannot be amended unilaterally. | F8: Mandatory | G8: Always | H8: =IF(IFERROR(INDEX(References!$D$28:$D$36,MATCH($G8,References!$B$28:$B$36,0)),"No")="Yes","Applicable","Not applicable") -> Applicable | I8: Beyond the law | J8: The terms of large providers change by their nature. It is not reasonable to require the contract to be frozen. Organisations must nevertheless take this factor into account in their risk analysis. Measures can mitigate this risk (e.g. advance notice, prohibition on lowering the level of protection, right of termination, the customer's ability to strengthen encryption, reversibility). | K8: (to be assessed) | N8: =IF($H8<>"Applicable","",IF(OR($K8="",$K8="(to be assessed)"),"",IF(OR($K8="Met",$K8="Not applicable"),"Acceptable",IF(AND($I8="Legal requirement",$K8="Not met"),"Not acceptable",IF($M8="","(to be decided)",IF(AND($I8="Legal requirement",$M8="Acceptable"),"Choice not permitted",$M8)))))) | P8: =IF($H8<>"Applicable","",IF(OR($K8="",$K8="(to be assessed)"),"To be assessed",IF($N8="Acceptable","OK",IF($N8="Acceptable subject to measures","OK subject to implementation of measures",IF($N8="Not acceptable","Not acceptable",IF($N8="Choice not permitted","To be corrected","To be decided")))))) -> To be assessed
B9: 2.1-03 | C9: The provider processes the data as the organisation would itself be permitted to: its contractual obligations reflect the legal conditions applicable to the organisation, including for user data. | D9: Ch. 1, p. 1; ch. 2.1, p. 3, n. 3 | E9: [Ch. 1, p. 1] [The public body] must ensure that third parties process the (personal) data as the public body would itself […] [Ch. 2.1, p. 3] The public body must draw up the provider's contractual obligations of conduct and diligence so that they meet all the conditions that it must itself comply with under the data protection legislation applicable to it. In particular, the provider may process only the data, and only in the manner, that the body itself would. [Note 3, p. 3] Principle of proportionality (data minimisation, retention period, etc.) and purpose limitation (the provider may not process personal data for purposes other than those permitted to the public body itself); both aspects also apply to the data concerning the users of the cloud services under section 2.4. | F9: Mandatory | G9: Always | H9: =IF(IFERROR(INDEX(References!$D$28:$D$36,MATCH($G9,References!$B$28:$B$36,0)),"No")="Yes","Applicable","Not applicable") -> Applicable | I9: Legal requirement | J9: Corresponds to the outsourcing regime under cantonal law. Check the DPA, in particular regarding the provider's own purposes (see 2.4-02). | K9: (to be assessed) | N9: =IF($H9<>"Applicable","",IF(OR($K9="",$K9="(to be assessed)"),"",IF(OR($K9="Met",$K9="Not applicable"),"Acceptable",IF(AND($I9="Legal requirement",$K9="Not met"),"Not acceptable",IF($M9="","(to be decided)",IF(AND($I9="Legal requirement",$M9="Acceptable"),"Choice not permitted",$M9)))))) | P9: =IF($H9<>"Applicable","",IF(OR($K9="",$K9="(to be assessed)"),"To be assessed",IF($N9="Acceptable","OK",IF($N9="Acceptable subject to measures","OK subject to implementation of measures",IF($N9="Not acceptable","Not acceptable",IF($N9="Choice not permitted","To be corrected","To be decided")))))) -> To be assessed
B10: 2.1-04 | C10: The provider assists in giving effect to the rights of data subjects (rectification, erasure). | D10: Ch. 2.1, p. 3 | E10: [Ch. 2.1, p. 3] In addition, the provider must assist in giving effect to the rights of data subjects arising from data protection legislation (claims for erasure and for rectification of data). | F10: Mandatory | G10: Always | H10: =IF(IFERROR(INDEX(References!$D$28:$D$36,MATCH($G10,References!$B$28:$B$36,0)),"No")="Yes","Applicable","Not applicable") -> Applicable | I10: Legal requirement | J10: Standard in DPAs (assistance to the controller). | K10: (to be assessed) | N10: =IF($H10<>"Applicable","",IF(OR($K10="",$K10="(to be assessed)"),"",IF(OR($K10="Met",$K10="Not applicable"),"Acceptable",IF(AND($I10="Legal requirement",$K10="Not met"),"Not acceptable",IF($M10="","(to be decided)",IF(AND($I10="Legal requirement",$M10="Acceptable"),"Choice not permitted",$M10)))))) | P10: =IF($H10<>"Applicable","",IF(OR($K10="",$K10="(to be assessed)"),"To be assessed",IF($N10="Acceptable","OK",IF($N10="Acceptable subject to measures","OK subject to implementation of measures",IF($N10="Not acceptable","Not acceptable",IF($N10="Choice not permitted","To be corrected","To be decided")))))) -> To be assessed
B11: 2.1-05 | C11: The contract is in principle governed by Swiss law, with jurisdiction in Switzerland, so that the provider's obligations can be enforced before easily accessible courts, under a legal system known to the organisation. | D11: Ch. 2.1, p. 3 | E11: [Ch. 2.1, p. 3] It must be possible to enforce the contractual obligations before courts easily accessible to the public body, under a legal system known to it. In principle, a contractual relationship must be governed by Swiss law, and a place of jurisdiction in Switzerland must be agreed for decisions on disputes arising from the contract. | F11: Principle | G11: Always | H11: =IF(IFERROR(INDEX(References!$D$28:$D$36,MATCH($G11,References!$B$28:$B$36,0)),"No")="Yes","Applicable","Not applicable") -> Applicable | I11: Good practice | J11: The law does not impose any particular governing law or jurisdiction. This is nevertheless a desirable requirement where possible. | K11: (to be assessed) | N11: =IF($H11<>"Applicable","",IF(OR($K11="",$K11="(to be assessed)"),"",IF(OR($K11="Met",$K11="Not applicable"),"Acceptable",IF(AND($I11="Legal requirement",$K11="Not met"),"Not acceptable",IF($M11="","(to be decided)",IF(AND($I11="Legal requirement",$M11="Acceptable"),"Choice not permitted",$M11)))))) | P11: =IF($H11<>"Applicable","",IF(OR($K11="",$K11="(to be assessed)"),"To be assessed",IF($N11="Acceptable","OK",IF($N11="Acceptable subject to measures","OK subject to implementation of measures",IF($N11="Not acceptable","Not acceptable",IF($N11="Choice not permitted","To be corrected","To be decided")))))) -> To be assessed
B12: 2.1-06 | C12: Foreign law or a foreign jurisdiction is agreed only in justified cases and provided that this creates no additional risk for fundamental rights, in particular if the data can be effectively protected by encryption against access by third parties (including the provider) or, except for special data, if the applicable data protection legislation offers an equivalent level of protection and effective and dissuasive sanctions apply to the provider (e.g. GDPR). | D12: Ch. 2.1, p. 3, n. 4-5 | E12: [Ch. 2.1, p. 3] In justified cases, it is possible to agree that the law of another State and a foreign place of jurisdiction apply if there is no additional risk for the fundamental rights of the data subjects, in particular where: – the data can be effectively protected by encryption against access by third parties (and even by the cloud service provider [section 2.3]), or, – provided that no special data are involved, the data protection legislation provides an equivalent level of protection and effective and dissuasive sanctions apply to the provider in the event of a breach (e.g. the EU GDPR). [Note 4, p. 3] The term “special data” is used in this document as a generic term for all personal data with a high need for protection, i.e. sensitive personal data, personality profiles and personal data subject to a legal duty of secrecy. [Note 5, p. 3] The parties cannot choose the data protection legislation; it follows from the personal, material and territorial scope of the data protection legislation itself. | F12: Option | G12: Foreign law | H12: =IF(IFERROR(INDEX(References!$D$28:$D$36,MATCH($G12,References!$B$28:$B$36,0)),"No")="Yes","Applicable","Not applicable") -> Applicable | I12: Beyond the law | J12: Requiring the absence of “any additional risk” is stricter than the law, which imposes no particular governing law or jurisdiction. The assessment concerns whether the contract can effectively be enforced. | K12: (to be assessed) | N12: =IF($H12<>"Applicable","",IF(OR($K12="",$K12="(to be assessed)"),"",IF(OR($K12="Met",$K12="Not applicable"),"Acceptable",IF(AND($I12="Legal requirement",$K12="Not met"),"Not acceptable",IF($M12="","(to be decided)",IF(AND($I12="Legal requirement",$M12="Acceptable"),"Choice not permitted",$M12)))))) | P12: =IF($H12<>"Applicable","",IF(OR($K12="",$K12="(to be assessed)"),"To be assessed",IF($N12="Acceptable","OK",IF($N12="Acceptable subject to measures","OK subject to implementation of measures",IF($N12="Not acceptable","Not acceptable",IF($N12="Choice not permitted","To be corrected","To be decided")))))) -> To be assessed
B13: 2.2 Places of data processing, including access by foreign authorities (p. 3-4)
B14: 2.2-01 | C14: The provider discloses the countries in which it operates the infrastructure processing the data, including user data. | D14: Ch. 2.2, p. 3 | E14: [Ch. 2.2, p. 3] The cloud service provider must disclose in which States it operates its cloud infrastructure for the processing of personal data (including those under section 2.4), so that the public body can assess the lawfulness of data transfers abroad and, in the risk assessment, take into account the risks linked to the locations of the servers. | F14: Mandatory | G14: Always | H14: =IF(IFERROR(INDEX(References!$D$28:$D$36,MATCH($G14,References!$B$28:$B$36,0)),"No")="Yes","Applicable","Not applicable") -> Applicable | I14: Legal requirement | J14: Important for assessing the lawfulness of disclosures abroad; standard in the documentation of large providers. | K14: (to be assessed) | N14: =IF($H14<>"Applicable","",IF(OR($K14="",$K14="(to be assessed)"),"",IF(OR($K14="Met",$K14="Not applicable"),"Acceptable",IF(AND($I14="Legal requirement",$K14="Not met"),"Not acceptable",IF($M14="","(to be decided)",IF(AND($I14="Legal requirement",$M14="Acceptable"),"Choice not permitted",$M14)))))) | P14: =IF($H14<>"Applicable","",IF(OR($K14="",$K14="(to be assessed)"),"To be assessed",IF($N14="Acceptable","OK",IF($N14="Acceptable subject to measures","OK subject to implementation of measures",IF($N14="Not acceptable","Not acceptable",IF($N14="Choice not permitted","To be corrected","To be decided")))))) -> To be assessed
B15: 2.2-02 | C15: Processing in Switzerland is preferred. | D15: Ch. 2.2, p. 4 | E15: [Ch. 2.2, p. 4] Data processing carried out in Switzerland must be preferred (security of the infrastructure, e.g. in relation to protection objectives such as availability, data integrity, accountability or traceability, as well as accessibility for audits, see section 2.7). | F15: Principle | G15: Always | H15: =IF(IFERROR(INDEX(References!$D$28:$D$36,MATCH($G15,References!$B$28:$B$36,0)),"No")="Yes","Applicable","Not applicable") -> Applicable | I15: Beyond the law | J15: No general obligation to localise data in Switzerland. Hosting in Switzerland does not remove the risk linked to the CLOUD Act or to the EU e-Evidence package (2.2-04). | K15: (to be assessed) | N15: =IF($H15<>"Applicable","",IF(OR($K15="",$K15="(to be assessed)"),"",IF(OR($K15="Met",$K15="Not applicable"),"Acceptable",IF(AND($I15="Legal requirement",$K15="Not met"),"Not acceptable",IF($M15="","(to be decided)",IF(AND($I15="Legal requirement",$M15="Acceptable"),"Choice not permitted",$M15)))))) | P15: =IF($H15<>"Applicable","",IF(OR($K15="",$K15="(to be assessed)"),"To be assessed",IF($N15="Acceptable","OK",IF($N15="Acceptable subject to measures","OK subject to implementation of measures",IF($N15="Not acceptable","Not acceptable",IF($N15="Choice not permitted","To be corrected","To be decided")))))) -> To be assessed
B16: 2.2-03 | C16: Any processing abroad, including access from abroad and the use of sub-processors, takes place only in a country ensuring equivalent protection or subject to recognised contractual safeguards; if the country allows access by authorities that does not meet the safeguards of fundamental rights, supplementary measures (in particular effective encryption) make the transfer lawful, failing which it is unlawful. | D16: Ch. 2.2, p. 4, n. 6-7; ch. 2.5, p. 7 | E16: [Ch. 2.2, p. 4] Data processing in foreign locations is lawful only in States that have an equivalent level of data protection or in which adequate data protection can be achieved by contract, in particular through recognised standard contractual clauses. This is not the case where, in the State concerned, access by authorities is possible that does not meet the constitutional guarantees of fundamental rights (principle of legality, principle of proportionality, rights of data subjects, access to independent courts). In that case, supplementary measures (in particular effective encryption) must be taken for the transfer of personal data abroad to be lawful. [Note 6, p. 4] Data processing abroad also includes access from a location abroad to data stored in Switzerland (e.g. for support services), since in this context the data are transmitted abroad, at least temporarily. [Note 7, p. 4] See Annex 1 to the Data Protection Ordinance (DPO), on which cantonal legislation relies directly and in part, and which can moreover be used as a reference. [Ch. 2.5, p. 7] […] if insufficient data protection due to possible access by authorities cannot be compensated for by contract, their use is unlawful. | F16: Mandatory | G16: Abroad | H16: =IF(IFERROR(INDEX(References!$D$28:$D$36,MATCH($G16,References!$B$28:$B$36,0)),"No")="Yes","Applicable","Not applicable") -> Applicable | I16: Legal requirement | J16: Corresponds to the cantonal rules on disclosure abroad, including sub-processors. Since 15.09.2024, the United States has been listed in Annex 1 DPO for companies certified under the DPF, a point the fact sheet does not address. | K16: (to be assessed) | N16: =IF($H16<>"Applicable","",IF(OR($K16="",$K16="(to be assessed)"),"",IF(OR($K16="Met",$K16="Not applicable"),"Acceptable",IF(AND($I16="Legal requirement",$K16="Not met"),"Not acceptable",IF($M16="","(to be decided)",IF(AND($I16="Legal requirement",$M16="Acceptable"),"Choice not permitted",$M16)))))) | P16: =IF($H16<>"Applicable","",IF(OR($K16="",$K16="(to be assessed)"),"To be assessed",IF($N16="Acceptable","OK",IF($N16="Acceptable subject to measures","OK subject to implementation of measures",IF($N16="Not acceptable","Not acceptable",IF($N16="Choice not permitted","To be corrected","To be decided")))))) -> To be assessed
B17: 2.2-04 | C17: The analysis takes into account the risk that a foreign authority may access the data under the CLOUD Act or similar law, including where the data are stored in Switzerland or in the EU. | D17: Ch. 2.2, p. 4, n. 8-10 | E17: [Ch. 2.2, p. 4] Caution: service providers subject to the CLOUD Act must grant US authorities a right of access to the stored data. This access must be granted even if the data are not stored in the United States but, for example, in a Member State of the European Union or in Switzerland. Access by an authority under the CLOUD Act or a similar legal instrument of another State would be considered an unlawful disclosure to third parties, because it would take place without a legal basis recognised by Switzerland. The risk of such a breach of the law must be taken into account in the analysis […]. [Note 8, p. 4] To determine who is subject to the CLOUD Act, see the US Department of Justice white paper of April 2019, in particular page 8: <https://www.justice.gov/opa/press-release/file/1153446/download>. [Note 9, p. 4] Clarifying Lawful Overseas Use of Data Act (CLOUD Act), H.R. 4943, <https://www.congress.gov/bill/115th-congress/house-bill/4943>. [Note 10, p. 4] Insofar as authorities can access the data without informing the responsible public body, the probability of occurrence cannot be assessed (because it is unverifiable), so that the focus is on the extent of the damage, for which the nature of the data is decisive (special personal data). | F17: Mandatory | G17: CLOUD Act | H17: =IF(IFERROR(INDEX(References!$D$28:$D$36,MATCH($G17,References!$B$28:$B$36,0)),"No")="Yes","Applicable","Not applicable") -> Applicable | I17: Legal requirement | J17: The risk of access outside the channels of international mutual assistance must be taken into account in the analysis under art. 320 and 321 SCC; to determine whether the provider is subject to the CLOUD Act, privatim refers to the US Department of Justice white paper (note 8). From a data protection perspective, nothing more can be required than the review carried out by the Federal Council. The method of note 10, which treats the probability as unverifiable, is questionable: it contradicts the risk-based approach of ch. 2 and 3, and the probability can be assessed on verifiable elements. The fact sheet does not take the EU e-Evidence package into account. | K17: (to be assessed) | N17: =IF($H17<>"Applicable","",IF(OR($K17="",$K17="(to be assessed)"),"",IF(OR($K17="Met",$K17="Not applicable"),"Acceptable",IF(AND($I17="Legal requirement",$K17="Not met"),"Not acceptable",IF($M17="","(to be decided)",IF(AND($I17="Legal requirement",$M17="Acceptable"),"Choice not permitted",$M17)))))) | P17: =IF($H17<>"Applicable","",IF(OR($K17="",$K17="(to be assessed)"),"To be assessed",IF($N17="Acceptable","OK",IF($N17="Acceptable subject to measures","OK subject to implementation of measures",IF($N17="Not acceptable","Not acceptable",IF($N17="Choice not permitted","To be corrected","To be decided")))))) -> To be assessed
B18: 2.2-05 | C18: The provider undertakes by contract to use all available remedies against the disclosure of the data and to inform the organisation immediately of requests for disclosure by authorities, to the extent it is permitted to do so. | D18: Ch. 2.2, p. 4 | E18: [Ch. 2.2, p. 4] […] and reduce this risk as far as possible through contractual measures (above all the cloud provider's obligation to use all available remedies to prevent the disclosure of the data and to inform the public body immediately of requests for disclosure by authorities, insofar as the cloud provider is permitted to do so). | F18: Mandatory | G18: CLOUD Act | H18: =IF(IFERROR(INDEX(References!$D$28:$D$36,MATCH($G18,References!$B$28:$B$36,0)),"No")="Yes","Applicable","Not applicable") -> Applicable | I18: Good practice | J18: Standard commitments of large providers (clause 15 of the standard contractual clauses); check their scope and the limits arising from gag orders. | K18: (to be assessed) | N18: =IF($H18<>"Applicable","",IF(OR($K18="",$K18="(to be assessed)"),"",IF(OR($K18="Met",$K18="Not applicable"),"Acceptable",IF(AND($I18="Legal requirement",$K18="Not met"),"Not acceptable",IF($M18="","(to be decided)",IF(AND($I18="Legal requirement",$M18="Acceptable"),"Choice not permitted",$M18)))))) | P18: =IF($H18<>"Applicable","",IF(OR($K18="",$K18="(to be assessed)"),"To be assessed",IF($N18="Acceptable","OK",IF($N18="Acceptable subject to measures","OK subject to implementation of measures",IF($N18="Not acceptable","Not acceptable",IF($N18="Choice not permitted","To be corrected","To be decided")))))) -> To be assessed
B19: 2.3 Confidentiality, protection of secrets, encryption and key management (p. 5-6)
B20: 2.3-01 | C20: All data, including user data, are protected against unauthorised access by third parties: encryption at least in transit, in line with the state of the art, and confidentiality measures during processing by the provider; if the provider holds the keys to sensitive data, it protects them and guarantees the integrity of the encryption. | D20: Ch. 2.3 a and b, p. 5, n. 12 | E20: [Ch. 2.3 a, p. 5] Personal data processed by the cloud provider (including those under section 2.4) must be protected against unauthorised access by third parties. Regardless of whether they are “ordinary” or special personal data, they must be encrypted, at least during transmission (“data in transit”), in line with the current state of technology. Confidentiality must be preserved by appropriate measures when the cloud provider processes the data. Where this is achieved by encryption, it should be noted that data stored in encrypted form (“data at rest”) do not, as a rule, remain encrypted during their subsequent processing (“data in process”). [Note 12, p. 5] This applies in particular when using platform-as-a-service (PaaS) and software-as-a-service (SaaS) offerings. [Ch. 2.3 b, p. 5] […] In addition, the cloud service provider must protect the keys against loss and theft, as well as against misuse and unauthorised access. It must also ensure that the data are not compromised during the encryption process. | F20: Mandatory | G20: Always | H20: =IF(IFERROR(INDEX(References!$D$28:$D$36,MATCH($G20,References!$B$28:$B$36,0)),"No")="Yes","Applicable","Not applicable") -> Applicable | I20: Good practice | J20: Reminder of the security duty; measures generally met by standard cloud services. As a rule, data do not remain encrypted while being processed in PaaS or SaaS mode. | K20: (to be assessed) | N20: =IF($H20<>"Applicable","",IF(OR($K20="",$K20="(to be assessed)"),"",IF(OR($K20="Met",$K20="Not applicable"),"Acceptable",IF(AND($I20="Legal requirement",$K20="Not met"),"Not acceptable",IF($M20="","(to be decided)",IF(AND($I20="Legal requirement",$M20="Acceptable"),"Choice not permitted",$M20)))))) | P20: =IF($H20<>"Applicable","",IF(OR($K20="",$K20="(to be assessed)"),"To be assessed",IF($N20="Acceptable","OK",IF($N20="Acceptable subject to measures","OK subject to implementation of measures",IF($N20="Not acceptable","Not acceptable",IF($N20="Choice not permitted","To be corrected","To be decided")))))) -> To be assessed
B21: 2.3-02 | C21: For sensitive data, higher confidentiality requirements are set and integrated into risk management. | D21: Ch. 2.3 b, p. 5 | E21: [Ch. 2.3 b, p. 5] In the case of sensitive personal data, account must also be taken of the fact that several or all of the confidentiality risks mentioned here exist for cloud services. Higher requirements must then be set to preserve the confidentiality of the data and taken into account in risk management […] | F21: Mandatory | G21: Sensitive data | H21: =IF(IFERROR(INDEX(References!$D$28:$D$36,MATCH($G21,References!$B$28:$B$36,0)),"No")="Yes","Applicable","Not applicable") -> Applicable | I21: Good practice | J21: Consistent with the proportionality of security measures; the required level depends on the concrete interest of the data, not only on their classification (see G3). Moreover, if measures deemed appropriate for “ordinary” data can also be sufficient for sensitive data, additional measures are not automatically necessary. | K21: (to be assessed) | N21: =IF($H21<>"Applicable","",IF(OR($K21="",$K21="(to be assessed)"),"",IF(OR($K21="Met",$K21="Not applicable"),"Acceptable",IF(AND($I21="Legal requirement",$K21="Not met"),"Not acceptable",IF($M21="","(to be decided)",IF(AND($I21="Legal requirement",$M21="Acceptable"),"Choice not permitted",$M21)))))) | P21: =IF($H21<>"Applicable","",IF(OR($K21="",$K21="(to be assessed)"),"To be assessed",IF($N21="Acceptable","OK",IF($N21="Acceptable subject to measures","OK subject to implementation of measures",IF($N21="Not acceptable","Not acceptable",IF($N21="Choice not permitted","To be corrected","To be decided")))))) -> To be assessed
B22: 2.3-03 | C22: Sensitive data are encrypted by the organisation itself, with keys available only to it and protected against loss, theft and misuse. | D22: Ch. 2.3 b, p. 5, n. 13 | E22: [Ch. 2.3 b, p. 5] The data must be encrypted and the encryption must be carried out by the public body. The keys must be available only to the public body. They must be protected against loss and theft, as well as against misuse and unauthorised access. [Note 13, p. 5] Likewise, see the technological considerations for the secure processing of sensitive information by several parties issued by the Federal Office for Cybersecurity (OFCS/BACS) on 28 May 2026 (ch. 2.2 T-1), available at: <https://www.bacs.admin.ch/fr/26-tech-sens-info-fr>. | F22: Principle | G22: Sensitive data | H22: =IF(IFERROR(INDEX(References!$D$28:$D$36,MATCH($G22,References!$B$28:$B$36,0)),"No")="Yes","Applicable","Not applicable") -> Applicable | I22: Beyond the law | J22: No legal basis requires client-side encryption for all sensitive data; the law requires measures appropriate to the risk. The rule makes many SaaS functions unusable and must be assessed in light of the benefits and other measures (see G3 and G5). | K22: (to be assessed) | N22: =IF($H22<>"Applicable","",IF(OR($K22="",$K22="(to be assessed)"),"",IF(OR($K22="Met",$K22="Not applicable"),"Acceptable",IF(AND($I22="Legal requirement",$K22="Not met"),"Not acceptable",IF($M22="","(to be decided)",IF(AND($I22="Legal requirement",$M22="Acceptable"),"Choice not permitted",$M22)))))) | P22: =IF($H22<>"Applicable","",IF(OR($K22="",$K22="(to be assessed)"),"To be assessed",IF($N22="Acceptable","OK",IF($N22="Acceptable subject to measures","OK subject to implementation of measures",IF($N22="Not acceptable","Not acceptable",IF($N22="Choice not permitted","To be corrected","To be decided")))))) -> To be assessed
B23: 2.3-04 | C23: Where encryption of sensitive data is managed by the provider, the organisation establishes that this choice does not create an unacceptable risk for fundamental rights; the provider undertakes to use the keys only with the organisation's express consent, and accesses are recorded in a log. | D23: Ch. 2.3 b, p. 5 | E23: [Ch. 2.3 b, p. 5] Encryption by the cloud service provider may be considered only if this does not expose the fundamental rights of the data subjects to unacceptable risks (which the public body must set out in a relevant manner). In that case, the level at which encryption takes place (application, database or hard disk) must be taken into account. The cloud service provider may hold the keys if it undertakes by contract to use them only with the express consent of the public body. A log of accesses must be kept. […] | F23: Mandatory | G23: Provider keys | H23: =IF(IFERROR(INDEX(References!$D$28:$D$36,MATCH($G23,References!$B$28:$B$36,0)),"No")="Yes","Applicable","Not applicable") -> Applicable | I23: Good practice | J23: Requires documented justification, which is consistent with the risk-based approach. Express consent and logging: “customer lockbox”-type mechanisms or a dedicated hardware security module, with their exceptions. | K23: (to be assessed) | N23: =IF($H23<>"Applicable","",IF(OR($K23="",$K23="(to be assessed)"),"",IF(OR($K23="Met",$K23="Not applicable"),"Acceptable",IF(AND($I23="Legal requirement",$K23="Not met"),"Not acceptable",IF($M23="","(to be decided)",IF(AND($I23="Legal requirement",$M23="Acceptable"),"Choice not permitted",$M23)))))) | P23: =IF($H23<>"Applicable","",IF(OR($K23="",$K23="(to be assessed)"),"To be assessed",IF($N23="Acceptable","OK",IF($N23="Acceptable subject to measures","OK subject to implementation of measures",IF($N23="Not acceptable","Not acceptable",IF($N23="Choice not permitted","To be corrected","To be decided")))))) -> To be assessed
B24: 2.3-05 | C24: According to privatim, outsourcing sensitive data or data subject to a legal duty of secrecy to SaaS solutions of large international providers (e.g. Microsoft, Google, AWS, SAP) is not permissible in most cases, due to a risk considered unacceptable; according to the expert opinion it cites, outsourcing sensitive data to the cloud of a US provider constitutes a serious interference that cannot be based on a general legal authorisation to outsource. | D24: Ch. 2.3 b, p. 5, n. 14; ch. 2.2, p. 4, n. 11 | E24: [Ch. 2.3 b, p. 5] Outsourcing sensitive personal data or personal data subject to a legal duty of secrecy to SaaS solutions of large international providers (such as Microsoft, Google, AWS and SAP) is not permissible in most cases because of the unacceptable risk. [Note 14, p. 5] See the Resolution on outsourcing data processing to the cloud of 18 November 2025 […]. [Ch. 2.2, p. 4] According to an expert opinion of the University of Basel, outsourcing sensitive personal data to the cloud of a US provider constitutes a serious interference with informational self-determination that cannot be justified by a general legal authorisation to use a processor. [Note 11, p. 4] MARKUS SCHEFER/PHILIP GLASS, Der grundrechtskonforme Einsatz von M365 durch öffentliche Organe in der Schweiz – Eine Analyse am Beispiel des Kantons Zürich, Editions Weblaw, Bern 2023. | F24: Policy position | G24: SaaS + special data | H24: =IF(IFERROR(INDEX(References!$D$28:$D$36,MATCH($G24,References!$B$28:$B$36,0)),"No")="Yes","Applicable","Not applicable") -> Applicable | I24: Disputed | J24: No legal prohibition: the formal classification of the data is not the legal criterion for outsourcing or transfer, and the risk depends on the concrete interest of the data. The fact sheet itself reserves exceptions (“in most cases”). | K24: (to be assessed) | N24: =IF($H24<>"Applicable","",IF(OR($K24="",$K24="(to be assessed)"),"",IF(OR($K24="Met",$K24="Not applicable"),"Acceptable",IF(AND($I24="Legal requirement",$K24="Not met"),"Not acceptable",IF($M24="","(to be decided)",IF(AND($I24="Legal requirement",$M24="Acceptable"),"Choice not permitted",$M24)))))) | P24: =IF($H24<>"Applicable","",IF(OR($K24="",$K24="(to be assessed)"),"To be assessed",IF($N24="Acceptable","OK",IF($N24="Acceptable subject to measures","OK subject to implementation of measures",IF($N24="Not acceptable","Not acceptable",IF($N24="Choice not permitted","To be corrected","To be decided")))))) -> To be assessed
B25: 2.3-06 | C25: Where data subject to official or professional secrecy are accessible to the provider (or its sub-processors), the conditions laid down in art. 320 and 321 SCC are met in the specific case; in particular, the provider and, where applicable, its sub-processors are properly integrated as auxiliaries in accordance with the applicable requirements (no legal or contractual obligation precludes outsourcing). | D25: Ch. 1, p. 1; ch. 2.3 c, p. 6 | E25: [Ch. 1, p. 1] [The public body] may outsource data processing if legal duties of secrecy (such as official secrecy under art. 320 SCC, special duties of secrecy or professional secrecy) or contractual instruments do not preclude it in the specific context […] [Ch. 2.3 c, p. 6] Personal data subject to a legal duty of secrecy may be accessible to the cloud provider (and, where applicable, to its sub-processor) only insofar as the provision on the protection of the secret in question allows the use of auxiliaries. This provision must also determine which auxiliary persons may be considered and which requirements must be met to ensure that secrets are protected. Breaching the provisions on the protection of secrecy without a recognised justification must be considered a legal obstacle to outsourcing, and not merely a risk. | F25: Mandatory | G25: Legal secrecy | H25: =IF(IFERROR(INDEX(References!$D$28:$D$36,MATCH($G25,References!$B$28:$B$36,0)),"No")="Yes","Applicable","Not applicable") -> Applicable | I25: Legal requirement | J25: Art. 320 no. 1 SCC expressly covers auxiliaries of an authority (wording in force since 1.1.2023) and art. 321 no. 1 SCC auxiliaries of the professions concerned. These provisions do not define auxiliaries: the criteria result from case law and legal writing, which accept that a service provider may be one. Document these criteria (instructions, integration, confidentiality undertaking) rather than looking for a specific provision. The decisive question is whether there is a disclosure (auxiliary, data unintelligible to the provider) or a justification (consent, authorisation). | K25: (to be assessed) | N25: =IF($H25<>"Applicable","",IF(OR($K25="",$K25="(to be assessed)"),"",IF(OR($K25="Met",$K25="Not applicable"),"Acceptable",IF(AND($I25="Legal requirement",$K25="Not met"),"Not acceptable",IF($M25="","(to be decided)",IF(AND($I25="Legal requirement",$M25="Acceptable"),"Choice not permitted",$M25)))))) | P25: =IF($H25<>"Applicable","",IF(OR($K25="",$K25="(to be assessed)"),"To be assessed",IF($N25="Acceptable","OK",IF($N25="Acceptable subject to measures","OK subject to implementation of measures",IF($N25="Not acceptable","Not acceptable",IF($N25="Choice not permitted","To be corrected","To be decided")))))) -> To be assessed
B26: 2.4 Data concerning the users of the cloud services (p. 6)
B27: 2.4-01 | C27: Data generated by the provider or its services (secondary data, telemetry, logs) are processed with the same diligence as the data processed by the organisation, subject to the same contractual provisions and protected in the same way; respect for data subjects' rights and deletion after an appropriate or legally required retention period are regulated, taking into account the potentially sensitive nature of these data. | D27: Ch. 2.4, p. 6 | E27: [Ch. 2.4, p. 6] As a rule, (cloud) providers process not only the personal data transmitted by the public body in the cloud services (in particular content data), but also data generated by themselves or their services through the users (e.g. secondary, telemetry or log data). These additional personal data must be processed with the same diligence as those processed by the public body to perform its tasks. They must be subject to the same contractual provisions, and the lawfulness of their processing and their protection must be guaranteed in the same way. In particular, respect for the rights of data subjects and deletion after an appropriate or legally required retention period must be regulated and supported by appropriate measures. […] Depending on the context, it should be noted that the additional personal data may become sensitive personal data (e.g. where connection data indicate that the data subject is staying in a psychiatric hospital or a prison). | F27: Mandatory | G27: Always | H27: =IF(IFERROR(INDEX(References!$D$28:$D$36,MATCH($G27,References!$B$28:$B$36,0)),"No")="Yes","Applicable","Not applicable") -> Applicable | I27: Legal requirement | K27: (to be assessed) | N27: =IF($H27<>"Applicable","",IF(OR($K27="",$K27="(to be assessed)"),"",IF(OR($K27="Met",$K27="Not applicable"),"Acceptable",IF(AND($I27="Legal requirement",$K27="Not met"),"Not acceptable",IF($M27="","(to be decided)",IF(AND($I27="Legal requirement",$M27="Acceptable"),"Choice not permitted",$M27)))))) | P27: =IF($H27<>"Applicable","",IF(OR($K27="",$K27="(to be assessed)"),"To be assessed",IF($N27="Acceptable","OK",IF($N27="Acceptable subject to measures","OK subject to implementation of measures",IF($N27="Not acceptable","Not acceptable",IF($N27="Choice not permitted","To be corrected","To be decided")))))) -> To be assessed
B28: 2.4-02 | C28: These data are recorded and used only for purposes that would also be permitted to the organisation and are disclosed to it transparently; processing for other purposes is lawful only if the data are collected anonymously, anonymised beforehand or effectively pseudonymised. | D28: Ch. 2.4, p. 6 | E28: [Ch. 2.4, p. 6] These additional personal data must be recorded and used exclusively for purposes that would also be permitted to the public body; they must be disclosed to the body transparently. In general, these are purposes that are not personal in nature. Examples include the planning and reporting of technical capacity, maintaining the security of information and services, technical maintenance of the infrastructure or recording usage-based charges. Processing for other purposes is lawful only if the data are collected anonymously, anonymised beforehand or effectively pseudonymised. | F28: Mandatory | G28: Always | H28: =IF(IFERROR(INDEX(References!$D$28:$D$36,MATCH($G28,References!$B$28:$B$36,0)),"No")="Yes","Applicable","Not applicable") -> Applicable | I28: Legal requirement | J28: Consistent with the purpose limitation principle; check processing “for legitimate business purposes” provided for in some DPAs. | K28: (to be assessed) | N28: =IF($H28<>"Applicable","",IF(OR($K28="",$K28="(to be assessed)"),"",IF(OR($K28="Met",$K28="Not applicable"),"Acceptable",IF(AND($I28="Legal requirement",$K28="Not met"),"Not acceptable",IF($M28="","(to be decided)",IF(AND($I28="Legal requirement",$M28="Acceptable"),"Choice not permitted",$M28)))))) | P28: =IF($H28<>"Applicable","",IF(OR($K28="",$K28="(to be assessed)"),"To be assessed",IF($N28="Acceptable","OK",IF($N28="Acceptable subject to measures","OK subject to implementation of measures",IF($N28="Not acceptable","Not acceptable",IF($N28="Choice not permitted","To be corrected","To be decided")))))) -> To be assessed
B29: 2.5 Subcontracting agreements (p. 6-7)
B30: 2.5-01 | C30: Before the contract is concluded, the provider discloses its sub-processors individually (including its parent company and subsidiaries), and the contract states how it instructs and monitors them, including chains of sub-processors. | D30: Ch. 2.5, p. 6 | E30: [Ch. 2.5, p. 6] The public body also remains responsible for the data processing that the cloud provider in turn transfers to third parties (including the parent company and subsidiaries). This is why, before the contract between the public body and the provider is concluded, the provider must disclose its subcontracting agreements individually so that the public body can assess the lawfulness of data transfers abroad and the risks relating to all the cloud service providers involved. The contract must specify the measures by which the cloud provider instructs and monitors its sub-processors (including relationships with [chains of] sub-sub-processors). | F30: Mandatory | G30: Always | H30: =IF(IFERROR(INDEX(References!$D$28:$D$36,MATCH($G30,References!$B$28:$B$36,0)),"No")="Yes","Applicable","Not applicable") -> Applicable | I30: Legal requirement | J30: The lists published online by large providers in principle meet this requirement if they are sufficiently precise (country, functions); flow-down clauses are standard. | K30: (to be assessed) | N30: =IF($H30<>"Applicable","",IF(OR($K30="",$K30="(to be assessed)"),"",IF(OR($K30="Met",$K30="Not applicable"),"Acceptable",IF(AND($I30="Legal requirement",$K30="Not met"),"Not acceptable",IF($M30="","(to be decided)",IF(AND($I30="Legal requirement",$M30="Acceptable"),"Choice not permitted",$M30)))))) | P30: =IF($H30<>"Applicable","",IF(OR($K30="",$K30="(to be assessed)"),"To be assessed",IF($N30="Acceptable","OK",IF($N30="Acceptable subject to measures","OK subject to implementation of measures",IF($N30="Not acceptable","Not acceptable",IF($N30="Choice not permitted","To be corrected","To be decided")))))) -> To be assessed
B31: 2.5-02 | C31: Sub-processors located in countries without an adequate level of protection are excluded. | D31: Ch. 2.5, p. 7 | E31: [Ch. 2.5, p. 7] Sub-processors from countries without an adequate level of data protection should be excluded; […] | F31: Recommendation | G31: Abroad | H31: =IF(IFERROR(INDEX(References!$D$28:$D$36,MATCH($G31,References!$B$28:$B$36,0)),"No")="Yes","Applicable","Not applicable") -> Applicable | I31: Beyond the law | J31: The law allows recipients in non-adequate countries subject to appropriate safeguards (see 2.2-03); exclusion is only a recommendation. | K31: (to be assessed) | N31: =IF($H31<>"Applicable","",IF(OR($K31="",$K31="(to be assessed)"),"",IF(OR($K31="Met",$K31="Not applicable"),"Acceptable",IF(AND($I31="Legal requirement",$K31="Not met"),"Not acceptable",IF($M31="","(to be decided)",IF(AND($I31="Legal requirement",$M31="Acceptable"),"Choice not permitted",$M31)))))) | P31: =IF($H31<>"Applicable","",IF(OR($K31="",$K31="(to be assessed)"),"To be assessed",IF($N31="Acceptable","OK",IF($N31="Acceptable subject to measures","OK subject to implementation of measures",IF($N31="Not acceptable","Not acceptable",IF($N31="Choice not permitted","To be corrected","To be decided")))))) -> To be assessed
B32: 2.5-03 | C32: During the term of the contract, any change in sub-processing is notified in advance, with a possibility of termination. | D32: Ch. 2.5, p. 7 | E32: [Ch. 2.5, p. 7] During the term of the contract, any change to the subcontracting agreements must be notified to the public body in advance, with the possibility of termination. | F32: Mandatory | G32: Always | H32: =IF(IFERROR(INDEX(References!$D$28:$D$36,MATCH($G32,References!$B$28:$B$36,0)),"No")="Yes","Applicable","Not applicable") -> Applicable | I32: Legal requirement | J32: Prior information and a right to object are standard; the right of termination is a contractual term to be negotiated. | K32: (to be assessed) | N32: =IF($H32<>"Applicable","",IF(OR($K32="",$K32="(to be assessed)"),"",IF(OR($K32="Met",$K32="Not applicable"),"Acceptable",IF(AND($I32="Legal requirement",$K32="Not met"),"Not acceptable",IF($M32="","(to be decided)",IF(AND($I32="Legal requirement",$M32="Acceptable"),"Choice not permitted",$M32)))))) | P32: =IF($H32<>"Applicable","",IF(OR($K32="",$K32="(to be assessed)"),"To be assessed",IF($N32="Acceptable","OK",IF($N32="Acceptable subject to measures","OK subject to implementation of measures",IF($N32="Not acceptable","Not acceptable",IF($N32="Choice not permitted","To be corrected","To be decided")))))) -> To be assessed
B33: 2.6 Notification duties (p. 7)
